2019-06-06 07:07:45,183 - util.py[DEBUG]: Cloud-init v. 19.1-1-gbaa47854-0ubuntu1~16.04.1 running 'init-local' at Thu, 06 Jun 2019 07:07:44 +0000. Up 16.11 seconds.
2019-06-06 07:07:45,183 - main.py[DEBUG]: No kernel command line url found.
2019-06-06 07:07:45,183 - main.py[DEBUG]: Closing stdin.
2019-06-06 07:07:45,210 - util.py[DEBUG]: Writing to /var/log/cloud-init.log - ab: [644] 0 bytes
2019-06-06 07:07:45,214 - util.py[DEBUG]: Changing the ownership of /var/log/cloud-init.log to 104:4
2019-06-06 07:07:45,217 - util.py[DEBUG]: Attempting to remove /var/lib/cloud/instance/boot-finished
2019-06-06 07:07:45,217 - util.py[DEBUG]: Attempting to remove /var/lib/cloud/data/no-net
2019-06-06 07:07:45,218 - handlers.py[DEBUG]: start: init-local/check-cache: attempting to read from cache [check]
2019-06-06 07:07:45,218 - util.py[DEBUG]: Reading from /var/lib/cloud/instance/obj.pkl (quiet=False)
2019-06-06 07:07:45,218 - stages.py[DEBUG]: no cache found
2019-06-06 07:07:45,219 - handlers.py[DEBUG]: finish: init-local/check-cache: SUCCESS: no cache found
2019-06-06 07:07:45,219 - util.py[DEBUG]: Attempting to remove /var/lib/cloud/instance
2019-06-06 07:07:45,236 - stages.py[DEBUG]: Using distro class <class 'cloudinit.distros.ubuntu.Distro'>
2019-06-06 07:07:45,238 - __init__.py[DEBUG]: Looking for data source in: ['NoCloud', 'ConfigDrive', 'OpenNebula', 'DigitalOcean', 'Azure', 'AltCloud', 'OVF', 'MAAS', 'GCE', 'OpenStack', 'CloudSigma', 'SmartOS', 'Bigstep', 'Scaleway', 'AliYun', 'Ec2', 'CloudStack', 'None'], via packages ['', 'cloudinit.sources'] that matches dependencies ['FILESYSTEM']
2019-06-06 07:07:45,406 - util.py[DEBUG]: Reading from /etc/os-release (quiet=False)
2019-06-06 07:07:45,407 - util.py[DEBUG]: Read 298 bytes from /etc/os-release
2019-06-06 07:07:45,545 - __init__.py[DEBUG]: Searching for local data source in: ['DataSourceNoCloud', 'DataSourceConfigDrive', 'DataSourceOpenNebula', 'DataSourceDigitalOcean', 'DataSourceAzure', 'DataSourceOVF', 'DataSourceOpenStackLocal', 'DataSourceCloudSigma', 'DataSourceSmartOS', 'DataSourceScaleway', 'DataSourceEc2Local']
2019-06-06 07:07:45,545 - handlers.py[DEBUG]: start: init-local/search-NoCloud: searching for local data from DataSourceNoCloud
2019-06-06 07:07:45,546 - __init__.py[DEBUG]: Seeing if we can get any data from <class 'cloudinit.sources.DataSourceNoCloud.DataSourceNoCloud'>
2019-06-06 07:07:45,546 - __init__.py[DEBUG]: Update datasource metadata and network config due to events: New instance first boot
2019-06-06 07:07:45,547 - util.py[DEBUG]: Running command ['systemd-detect-virt', '--quiet', '--container'] with allowed return codes [0] (shell=False, capture=True)
2019-06-06 07:07:45,555 - util.py[DEBUG]: Running command ['running-in-container'] with allowed return codes [0] (shell=False, capture=True)
2019-06-06 07:07:45,563 - util.py[DEBUG]: Running command ['lxc-is-container'] with allowed return codes [0] (shell=False, capture=True)
2019-06-06 07:07:45,570 - util.py[DEBUG]: Reading from /proc/1/environ (quiet=False)
2019-06-06 07:07:45,571 - util.py[DEBUG]: Read 18 bytes from /proc/1/environ
2019-06-06 07:07:45,572 - util.py[DEBUG]: Reading from /proc/self/status (quiet=False)
2019-06-06 07:07:45,572 - util.py[DEBUG]: Read 912 bytes from /proc/self/status
2019-06-06 07:07:45,572 - util.py[DEBUG]: querying dmi data /sys/class/dmi/id/product_serial
2019-06-06 07:07:45,573 - util.py[DEBUG]: did not find /sys/class/dmi/id/product_serial
2019-06-06 07:07:45,574 - util.py[DEBUG]: Running command ['/usr/sbin/dmidecode', '--string', 'system-serial-number'] with allowed return codes [0] (shell=False, capture=True)
2019-06-06 07:07:45,593 - util.py[DEBUG]: failed dmidecode cmd: ['/usr/sbin/dmidecode', '--string', 'system-serial-number']
Unexpected error while running command.
Command: ['/usr/sbin/dmidecode', '--string', 'system-serial-number']
Exit code: 1
Reason: -
Stdout: 
Stderr: /dev/mem: Operation not permitted
2019-06-06 07:07:45,594 - util.py[DEBUG]: Reading from /var/lib/cloud/seed/nocloud/user-data (quiet=False)
2019-06-06 07:07:45,595 - util.py[DEBUG]: Reading from /var/lib/cloud/seed/nocloud/meta-data (quiet=False)
2019-06-06 07:07:45,595 - util.py[DEBUG]: Reading from /var/lib/cloud/seed/nocloud/vendor-data (quiet=False)
2019-06-06 07:07:45,595 - util.py[DEBUG]: Reading from /var/lib/cloud/seed/nocloud/network-config (quiet=False)
2019-06-06 07:07:45,596 - util.py[DEBUG]: Reading from /var/lib/cloud/seed/nocloud-net/user-data (quiet=False)
2019-06-06 07:07:45,596 - util.py[DEBUG]: Reading from /var/lib/cloud/seed/nocloud-net/meta-data (quiet=False)
2019-06-06 07:07:45,596 - util.py[DEBUG]: Reading from /var/lib/cloud/seed/nocloud-net/vendor-data (quiet=False)
2019-06-06 07:07:45,596 - util.py[DEBUG]: Reading from /var/lib/cloud/seed/nocloud-net/network-config (quiet=False)
2019-06-06 07:07:45,597 - util.py[DEBUG]: Running command ['blkid', '-odevice', '/dev/sr0'] with allowed return codes [0, 2] (shell=False, capture=True)
2019-06-06 07:07:45,605 - util.py[DEBUG]: Running command ['blkid', '-odevice', '/dev/sr1'] with allowed return codes [0, 2] (shell=False, capture=True)
2019-06-06 07:07:45,614 - util.py[DEBUG]: Running command ['blkid', '-tTYPE=vfat', '-odevice'] with allowed return codes [0, 2] (shell=False, capture=True)
2019-06-06 07:07:45,834 - util.py[DEBUG]: Running command ['blkid', '-tTYPE=iso9660', '-odevice'] with allowed return codes [0, 2] (shell=False, capture=True)
2019-06-06 07:07:45,962 - util.py[DEBUG]: Running command ['blkid', '-tLABEL=CIDATA', '-odevice'] with allowed return codes [0, 2] (shell=False, capture=True)
2019-06-06 07:07:46,092 - util.py[DEBUG]: Running command ['blkid', '-tLABEL=cidata', '-odevice'] with allowed return codes [0, 2] (shell=False, capture=True)
2019-06-06 07:07:46,220 - __init__.py[DEBUG]: Datasource DataSourceNoCloud [seed=None][dsmode=net] not updated for events: New instance first boot
2019-06-06 07:07:46,221 - handlers.py[DEBUG]: finish: init-local/search-NoCloud: SUCCESS: no local data found from DataSourceNoCloud
2019-06-06 07:07:46,221 - handlers.py[DEBUG]: start: init-local/search-ConfigDrive: searching for local data from DataSourceConfigDrive
2019-06-06 07:07:46,221 - __init__.py[DEBUG]: Seeing if we can get any data from <class 'cloudinit.sources.DataSourceConfigDrive.DataSourceConfigDrive'>
2019-06-06 07:07:46,222 - __init__.py[DEBUG]: Update datasource metadata and network config due to events: New instance first boot
2019-06-06 07:07:46,223 - util.py[DEBUG]: Running command ['blkid', '-odevice', '/dev/sr0'] with allowed return codes [0, 2] (shell=False, capture=True)
2019-06-06 07:07:46,231 - util.py[DEBUG]: Running command ['blkid', '-odevice', '/dev/sr1'] with allowed return codes [0, 2] (shell=False, capture=True)
2019-06-06 07:07:46,240 - util.py[DEBUG]: Running command ['blkid', '-odevice', '/dev/cd0'] with allowed return codes [0, 2] (shell=False, capture=True)
2019-06-06 07:07:46,248 - util.py[DEBUG]: Running command ['blkid', '-odevice', '/dev/cd1'] with allowed return codes [0, 2] (shell=False, capture=True)
2019-06-06 07:07:46,257 - util.py[DEBUG]: Running command ['blkid', '-tTYPE=vfat', '-odevice'] with allowed return codes [0, 2] (shell=False, capture=True)
2019-06-06 07:07:46,385 - util.py[DEBUG]: Running command ['blkid', '-tTYPE=iso9660', '-odevice'] with allowed return codes [0, 2] (shell=False, capture=True)
2019-06-06 07:07:46,510 - util.py[DEBUG]: Running command ['blkid', '-tLABEL=config-2', '-odevice'] with allowed return codes [0, 2] (shell=False, capture=True)
2019-06-06 07:07:46,638 - util.py[DEBUG]: Running command ['blkid', '-tLABEL=CONFIG-2', '-odevice'] with allowed return codes [0, 2] (shell=False, capture=True)
2019-06-06 07:07:46,766 - DataSourceConfigDrive.py[DEBUG]: devices=[] dslist=['NoCloud', 'ConfigDrive', 'OpenNebula', 'DigitalOcean', 'Azure', 'AltCloud', 'OVF', 'MAAS', 'GCE', 'OpenStack', 'CloudSigma', 'SmartOS', 'Bigstep', 'Scaleway', 'AliYun', 'Ec2', 'CloudStack', 'None']
2019-06-06 07:07:46,767 - __init__.py[DEBUG]: Datasource DataSourceConfigDrive [net,ver=None][source=None] not updated for events: New instance first boot
2019-06-06 07:07:46,768 - handlers.py[DEBUG]: finish: init-local/search-ConfigDrive: SUCCESS: no local data found from DataSourceConfigDrive
2019-06-06 07:07:46,768 - handlers.py[DEBUG]: start: init-local/search-OpenNebula: searching for local data from DataSourceOpenNebula
2019-06-06 07:07:46,769 - __init__.py[DEBUG]: Seeing if we can get any data from <class 'cloudinit.sources.DataSourceOpenNebula.DataSourceOpenNebula'>
2019-06-06 07:07:46,769 - __init__.py[DEBUG]: Update datasource metadata and network config due to events: New instance first boot
2019-06-06 07:07:46,770 - util.py[DEBUG]: Running command ['blkid', '-tLABEL=CONTEXT', '-odevice'] with allowed return codes [0, 2] (shell=False, capture=True)
2019-06-06 07:07:46,894 - util.py[DEBUG]: Running command ['blkid', '-tLABEL=CDROM', '-odevice'] with allowed return codes [0, 2] (shell=False, capture=True)
2019-06-06 07:07:55,776 - util.py[DEBUG]: Running command ['blkid', '-tTYPE=iso9660', '-odevice'] with allowed return codes [0, 2] (shell=False, capture=True)
2019-06-06 07:07:55,905 - __init__.py[DEBUG]: Datasource DataSourceOpenNebula [seed=None][dsmode=net] not updated for events: New instance first boot
2019-06-06 07:07:55,906 - handlers.py[DEBUG]: finish: init-local/search-OpenNebula: SUCCESS: no local data found from DataSourceOpenNebula
2019-06-06 07:07:55,906 - handlers.py[DEBUG]: start: init-local/search-DigitalOcean: searching for local data from DataSourceDigitalOcean
2019-06-06 07:07:55,906 - __init__.py[DEBUG]: Seeing if we can get any data from <class 'cloudinit.sources.DataSourceDigitalOcean.DataSourceDigitalOcean'>
2019-06-06 07:07:55,908 - __init__.py[DEBUG]: Update datasource metadata and network config due to events: New instance first boot
2019-06-06 07:07:55,908 - util.py[DEBUG]: Running command ['systemd-detect-virt', '--quiet', '--container'] with allowed return codes [0] (shell=False, capture=True)
2019-06-06 07:07:55,917 - util.py[DEBUG]: Running command ['running-in-container'] with allowed return codes [0] (shell=False, capture=True)
2019-06-06 07:07:55,924 - util.py[DEBUG]: Running command ['lxc-is-container'] with allowed return codes [0] (shell=False, capture=True)
2019-06-06 07:07:55,932 - util.py[DEBUG]: Reading from /proc/1/environ (quiet=False)
2019-06-06 07:07:55,933 - util.py[DEBUG]: Read 18 bytes from /proc/1/environ
2019-06-06 07:07:55,933 - util.py[DEBUG]: Reading from /proc/self/status (quiet=False)
2019-06-06 07:07:55,933 - util.py[DEBUG]: Read 912 bytes from /proc/self/status
2019-06-06 07:07:55,934 - util.py[DEBUG]: querying dmi data /sys/class/dmi/id/sys_vendor
2019-06-06 07:07:55,934 - util.py[DEBUG]: did not find /sys/class/dmi/id/sys_vendor
2019-06-06 07:07:55,935 - util.py[DEBUG]: Running command ['/usr/sbin/dmidecode', '--string', 'system-manufacturer'] with allowed return codes [0] (shell=False, capture=True)
2019-06-06 07:07:55,943 - util.py[DEBUG]: failed dmidecode cmd: ['/usr/sbin/dmidecode', '--string', 'system-manufacturer']
Unexpected error while running command.
Command: ['/usr/sbin/dmidecode', '--string', 'system-manufacturer']
Exit code: 1
Reason: -
Stdout: 
Stderr: /dev/mem: Operation not permitted
2019-06-06 07:07:55,944 - __init__.py[DEBUG]: Datasource DataSourceDigitalOcean not updated for events: New instance first boot
2019-06-06 07:07:55,944 - handlers.py[DEBUG]: finish: init-local/search-DigitalOcean: SUCCESS: no local data found from DataSourceDigitalOcean
2019-06-06 07:07:55,945 - handlers.py[DEBUG]: start: init-local/search-Azure: searching for local data from DataSourceAzure
2019-06-06 07:07:55,945 - __init__.py[DEBUG]: Seeing if we can get any data from <class 'cloudinit.sources.DataSourceAzure.DataSourceAzure'>
2019-06-06 07:07:55,947 - __init__.py[DEBUG]: Update datasource metadata and network config due to events: New instance first boot
2019-06-06 07:07:55,947 - handlers.py[DEBUG]: start: azure-ds/_get_data: _get_data
2019-06-06 07:07:55,948 - handlers.py[DEBUG]: start: azure-ds/check-platform-viability: found azure asset tag
2019-06-06 07:07:55,948 - util.py[DEBUG]: Running command ['systemd-detect-virt', '--quiet', '--container'] with allowed return codes [0] (shell=False, capture=True)
2019-06-06 07:07:55,957 - util.py[DEBUG]: Running command ['running-in-container'] with allowed return codes [0] (shell=False, capture=True)
2019-06-06 07:07:55,964 - util.py[DEBUG]: Running command ['lxc-is-container'] with allowed return codes [0] (shell=False, capture=True)
2019-06-06 07:07:55,972 - util.py[DEBUG]: Reading from /proc/1/environ (quiet=False)
2019-06-06 07:07:55,972 - util.py[DEBUG]: Read 18 bytes from /proc/1/environ
2019-06-06 07:07:55,973 - util.py[DEBUG]: Reading from /proc/self/status (quiet=False)
2019-06-06 07:07:55,973 - util.py[DEBUG]: Read 912 bytes from /proc/self/status
2019-06-06 07:07:55,974 - util.py[DEBUG]: querying dmi data /sys/class/dmi/id/chassis_asset_tag
2019-06-06 07:07:55,974 - util.py[DEBUG]: did not find /sys/class/dmi/id/chassis_asset_tag
2019-06-06 07:07:55,975 - util.py[DEBUG]: Running command ['/usr/sbin/dmidecode', '--string', 'chassis-asset-tag'] with allowed return codes [0] (shell=False, capture=True)
2019-06-06 07:07:55,983 - util.py[DEBUG]: failed dmidecode cmd: ['/usr/sbin/dmidecode', '--string', 'chassis-asset-tag']
Unexpected error while running command.
Command: ['/usr/sbin/dmidecode', '--string', 'chassis-asset-tag']
Exit code: 1
Reason: -
Stdout: 
Stderr: /dev/mem: Operation not permitted
2019-06-06 07:07:55,983 - DataSourceAzure.py[DEBUG]: Non-Azure DMI asset tag 'None' discovered.
2019-06-06 07:07:55,987 - handlers.py[DEBUG]: finish: azure-ds/check-platform-viability: SUCCESS: ("Non-Azure DMI asset tag '%s' discovered.", None)
2019-06-06 07:07:55,987 - handlers.py[DEBUG]: finish: azure-ds/_get_data: SUCCESS: _get_data
2019-06-06 07:07:55,987 - __init__.py[DEBUG]: Datasource DataSourceAzure [seed=None] not updated for events: New instance first boot
2019-06-06 07:07:55,988 - handlers.py[DEBUG]: finish: init-local/search-Azure: SUCCESS: no local data found from DataSourceAzure
2019-06-06 07:07:55,988 - handlers.py[DEBUG]: start: init-local/search-OVF: searching for local data from DataSourceOVF
2019-06-06 07:07:55,989 - __init__.py[DEBUG]: Seeing if we can get any data from <class 'cloudinit.sources.DataSourceOVF.DataSourceOVF'>
2019-06-06 07:07:55,989 - __init__.py[DEBUG]: Update datasource metadata and network config due to events: New instance first boot
2019-06-06 07:07:55,990 - util.py[DEBUG]: Running command ['systemd-detect-virt', '--quiet', '--container'] with allowed return codes [0] (shell=False, capture=True)
2019-06-06 07:07:55,999 - util.py[DEBUG]: Running command ['running-in-container'] with allowed return codes [0] (shell=False, capture=True)
2019-06-06 07:07:56,006 - util.py[DEBUG]: Running command ['lxc-is-container'] with allowed return codes [0] (shell=False, capture=True)
2019-06-06 07:07:56,014 - util.py[DEBUG]: Reading from /proc/1/environ (quiet=False)
2019-06-06 07:07:56,015 - util.py[DEBUG]: Read 18 bytes from /proc/1/environ
2019-06-06 07:07:56,015 - util.py[DEBUG]: Reading from /proc/self/status (quiet=False)
2019-06-06 07:07:56,015 - util.py[DEBUG]: Read 912 bytes from /proc/self/status
2019-06-06 07:07:56,016 - util.py[DEBUG]: querying dmi data /sys/class/dmi/id/product_name
2019-06-06 07:07:56,016 - util.py[DEBUG]: did not find /sys/class/dmi/id/product_name
2019-06-06 07:07:56,017 - util.py[DEBUG]: Running command ['/usr/sbin/dmidecode', '--string', 'system-product-name'] with allowed return codes [0] (shell=False, capture=True)
2019-06-06 07:07:56,025 - util.py[DEBUG]: failed dmidecode cmd: ['/usr/sbin/dmidecode', '--string', 'system-product-name']
Unexpected error while running command.
Command: ['/usr/sbin/dmidecode', '--string', 'system-product-name']
Exit code: 1
Reason: -
Stdout: 
Stderr: /dev/mem: Operation not permitted
2019-06-06 07:07:56,026 - DataSourceOVF.py[DEBUG]: No system-product-name found
2019-06-06 07:07:56,027 - util.py[DEBUG]: Reading from /proc/mounts (quiet=False)
2019-06-06 07:07:56,027 - util.py[DEBUG]: Read 942 bytes from /proc/mounts
2019-06-06 07:07:56,028 - util.py[DEBUG]: Fetched {'tracefs': {'mountpoint': '/sys/kernel/debug/tracing', 'opts': 'rw,relatime', 'fstype': 'tracefs'}, 'mqueue': {'mountpoint': '/dev/mqueue', 'opts': 'rw,relatime', 'fstype': 'mqueue'}, '/dev/root': {'mountpoint': '/', 'opts': 'rw,relatime,errors=remount-ro', 'fstype': 'ext3'}, 'cgroup': {'mountpoint': '/sys/fs/cgroup/systemd', 'opts': 'rw,nosuid,nodev,noexec,relatime,xattr,release_agent=/lib/systemd/systemd-cgroups-agent,name=systemd', 'fstype': 'cgroup'}, 'devtmpfs': {'mountpoint': '/dev', 'opts': 'rw,relatime,size=1496264k,nr_inodes=374066,mode=755', 'fstype': 'devtmpfs'}, 'debugfs': {'mountpoint': '/sys/kernel/debug', 'opts': 'rw,relatime', 'fstype': 'debugfs'}, 'sysfs': {'mountpoint': '/sys', 'opts': 'rw,nosuid,nodev,noexec,relatime', 'fstype': 'sysfs'}, 'tmpfs': {'mountpoint': '/sys/fs/cgroup', 'opts': 'ro,nosuid,nodev,noexec,mode=755', 'fstype': 'tmpfs'}, 'hugetlbfs': {'mountpoint': '/dev/hugepages', 'opts': 'rw,relatime,pagesize=2M', 'fstype': 'hugetlbfs'}, 'configfs': {'mountpoint': '/sys/kernel/config', 'opts': 'rw,relatime', 'fstype': 'configfs'}, 'devpts': {'mountpoint': '/dev/pts', 'opts': 'rw,nosuid,noexec,relatime,gid=5,mode=620,ptmxmode=000', 'fstype': 'devpts'}, 'proc': {'mountpoint': '/proc', 'opts': 'rw,nosuid,nodev,noexec,relatime', 'fstype': 'proc'}} mounts from proc
2019-06-06 07:07:56,028 - util.py[DEBUG]: Running command ['blkid', '-tTYPE=iso9660', '-odevice'] with allowed return codes [0, 2] (shell=False, capture=True)
2019-06-06 07:07:56,153 - __init__.py[DEBUG]: Datasource DataSourceOVF [seed=None] not updated for events: New instance first boot
2019-06-06 07:07:56,154 - handlers.py[DEBUG]: finish: init-local/search-OVF: SUCCESS: no local data found from DataSourceOVF
2019-06-06 07:07:56,154 - handlers.py[DEBUG]: start: init-local/search-OpenStackLocal: searching for local data from DataSourceOpenStackLocal
2019-06-06 07:07:56,154 - __init__.py[DEBUG]: Seeing if we can get any data from <class 'cloudinit.sources.DataSourceOpenStack.DataSourceOpenStackLocal'>
2019-06-06 07:07:56,155 - __init__.py[DEBUG]: Update datasource metadata and network config due to events: New instance first boot
2019-06-06 07:07:56,156 - util.py[DEBUG]: Reading from /sys/class/net/can0/name_assign_type (quiet=False)
2019-06-06 07:07:56,156 - util.py[DEBUG]: Reading from /sys/class/net/sit0/name_assign_type (quiet=False)
2019-06-06 07:07:56,157 - util.py[DEBUG]: Reading from /sys/class/net/eth0/name_assign_type (quiet=False)
2019-06-06 07:07:56,157 - __init__.py[DEBUG]: Found unstable nic names: ['can0', 'sit0', 'eth0']; calling udevadm settle
2019-06-06 07:07:56,159 - util.py[DEBUG]: Running command ['udevadm', 'settle'] with allowed return codes [0] (shell=False, capture=True)
2019-06-06 07:07:56,176 - util.py[DEBUG]: Waiting for udev events to settle took 0.017 seconds
2019-06-06 07:07:56,178 - util.py[DEBUG]: Reading from /sys/class/net/eth0/carrier (quiet=False)
2019-06-06 07:07:56,178 - util.py[DEBUG]: Reading from /sys/class/net/eth0/dormant (quiet=False)
2019-06-06 07:07:56,179 - util.py[DEBUG]: Reading from /sys/class/net/eth0/operstate (quiet=False)
2019-06-06 07:07:56,179 - util.py[DEBUG]: Read 5 bytes from /sys/class/net/eth0/operstate
2019-06-06 07:07:56,179 - util.py[DEBUG]: Reading from /sys/class/net/can0/carrier (quiet=False)
2019-06-06 07:07:56,180 - util.py[DEBUG]: Reading from /sys/class/net/can0/dormant (quiet=False)
2019-06-06 07:07:56,180 - util.py[DEBUG]: Reading from /sys/class/net/can0/operstate (quiet=False)
2019-06-06 07:07:56,181 - util.py[DEBUG]: Read 5 bytes from /sys/class/net/can0/operstate
2019-06-06 07:07:56,181 - util.py[DEBUG]: Reading from /sys/class/net/sit0/carrier (quiet=False)
2019-06-06 07:07:56,181 - util.py[DEBUG]: Reading from /sys/class/net/sit0/dormant (quiet=False)
2019-06-06 07:07:56,182 - util.py[DEBUG]: Reading from /sys/class/net/sit0/operstate (quiet=False)
2019-06-06 07:07:56,182 - util.py[DEBUG]: Read 5 bytes from /sys/class/net/sit0/operstate
2019-06-06 07:07:56,183 - util.py[DEBUG]: Reading from /sys/class/net/eth0/address (quiet=False)
2019-06-06 07:07:56,183 - util.py[DEBUG]: Read 18 bytes from /sys/class/net/eth0/address
2019-06-06 07:07:56,187 - dhcp.py[DEBUG]: Performing a dhcp discovery on eth0
2019-06-06 07:07:56,187 - util.py[DEBUG]: Copying /sbin/dhclient to /var/tmp/cloud-init/cloud-init-dhcp-ufzdg6cn/dhclient
2019-06-06 07:07:56,222 - util.py[DEBUG]: Running command ['ip', 'link', 'set', 'dev', 'eth0', 'up'] with allowed return codes [0] (shell=False, capture=True)
2019-06-06 07:07:56,263 - util.py[DEBUG]: Running command ['/var/tmp/cloud-init/cloud-init-dhcp-ufzdg6cn/dhclient', '-1', '-v', '-lf', '/var/tmp/cloud-init/cloud-init-dhcp-ufzdg6cn/dhcp.leases', '-pf', '/var/tmp/cloud-init/cloud-init-dhcp-ufzdg6cn/dhclient.pid', 'eth0', '-sf', '/bin/true'] with allowed return codes [0] (shell=False, capture=True)
2019-06-06 07:08:04,133 - util.py[DEBUG]: All files appeared after 0 seconds: ['/var/tmp/cloud-init/cloud-init-dhcp-ufzdg6cn/dhclient.pid', '/var/tmp/cloud-init/cloud-init-dhcp-ufzdg6cn/dhcp.leases']
2019-06-06 07:08:04,134 - util.py[DEBUG]: Reading from /var/tmp/cloud-init/cloud-init-dhcp-ufzdg6cn/dhclient.pid (quiet=False)
2019-06-06 07:08:04,134 - util.py[DEBUG]: Read 5 bytes from /var/tmp/cloud-init/cloud-init-dhcp-ufzdg6cn/dhclient.pid
2019-06-06 07:08:04,134 - util.py[DEBUG]: Reading from /proc/4115/stat (quiet=True)
2019-06-06 07:08:04,135 - util.py[DEBUG]: Read 275 bytes from /proc/4115/stat
2019-06-06 07:08:04,135 - dhcp.py[DEBUG]: killing dhclient with pid=4115
2019-06-06 07:08:04,138 - util.py[DEBUG]: Reading from /var/tmp/cloud-init/cloud-init-dhcp-ufzdg6cn/dhcp.leases (quiet=False)
2019-06-06 07:08:04,139 - util.py[DEBUG]: Read 677 bytes from /var/tmp/cloud-init/cloud-init-dhcp-ufzdg6cn/dhcp.leases
2019-06-06 07:08:04,140 - dhcp.py[DEBUG]: Received dhcp lease on eth0 for 172.23.19.138/255.255.252.0
2019-06-06 07:08:04,140 - __init__.py[DEBUG]: Attempting setup of ephemeral network on eth0 with 172.23.19.138/22 brd 172.23.19.255
2019-06-06 07:08:04,141 - util.py[DEBUG]: Running command ['ip', '-family', 'inet', 'addr', 'add', '172.23.19.138/22', 'broadcast', '172.23.19.255', 'dev', 'eth0'] with allowed return codes [0] (shell=False, capture=True)
2019-06-06 07:08:04,149 - util.py[DEBUG]: Running command ['ip', '-family', 'inet', 'link', 'set', 'dev', 'eth0', 'up'] with allowed return codes [0] (shell=False, capture=True)
2019-06-06 07:08:04,158 - util.py[DEBUG]: Running command ['ip', 'route', 'show', '0.0.0.0/0'] with allowed return codes [0] (shell=False, capture=True)
2019-06-06 07:08:04,167 - util.py[DEBUG]: Running command ['ip', '-4', 'route', 'add', '172.23.19.254', 'dev', 'eth0', 'src', '172.23.19.138'] with allowed return codes [0] (shell=False, capture=True)
2019-06-06 07:08:04,176 - util.py[DEBUG]: Running command ['ip', '-4', 'route', 'add', 'default', 'via', '172.23.19.254', 'dev', 'eth0'] with allowed return codes [0] (shell=False, capture=True)
2019-06-06 07:08:04,316 - util.py[DEBUG]: Resolving URL: http://169.254.169.254 took 0.131 seconds
2019-06-06 07:08:04,317 - url_helper.py[DEBUG]: [0/1] open 'http://169.254.169.254/openstack' with {'method': 'GET', 'timeout': 10.0, 'headers': {'User-Agent': 'Cloud-Init/19.1-1-gbaa47854-0ubuntu1~16.04.1'}, 'url': 'http://169.254.169.254/openstack', 'allow_redirects': True} configuration
2019-06-06 07:08:14,341 - url_helper.py[DEBUG]: Calling 'http://169.254.169.254/openstack' failed [10/-1s]: request error [HTTPConnectionPool(host='169.254.169.254', port=80): Max retries exceeded with url: /openstack (Caused by ConnectTimeoutError(<requests.packages.urllib3.connection.HTTPConnection object at 0x7f8e0bdcc0>, 'Connection to 169.254.169.254 timed out. (connect timeout=10.0)'))]
2019-06-06 07:08:21,984 - DataSourceOpenStack.py[DEBUG]: Giving up on OpenStack md from ['http://169.254.169.254/openstack'] after 17 seconds
2019-06-06 07:08:21,985 - util.py[DEBUG]: Crawl of metadata service took 17.800 seconds
2019-06-06 07:08:21,985 - util.py[DEBUG]: Running command ['ip', '-4', 'route', 'del', 'default', 'dev', 'eth0'] with allowed return codes [0] (shell=False, capture=True)
2019-06-06 07:08:21,994 - util.py[DEBUG]: Running command ['ip', '-4', 'route', 'del', '172.23.19.254', 'dev', 'eth0', 'src', '172.23.19.138'] with allowed return codes [0] (shell=False, capture=True)
2019-06-06 07:08:23,273 - util.py[DEBUG]: Running command ['ip', '-family', 'inet', 'link', 'set', 'dev', 'eth0', 'down'] with allowed return codes [0] (shell=False, capture=True)
2019-06-06 07:08:23,285 - util.py[DEBUG]: Running command ['ip', '-family', 'inet', 'addr', 'del', '172.23.19.138/22', 'dev', 'eth0'] with allowed return codes [0] (shell=False, capture=True)
2019-06-06 07:08:23,294 - util.py[WARNING]: No active metadata service found
2019-06-06 07:08:23,295 - util.py[DEBUG]: No active metadata service found
Traceback (most recent call last):
  File "/usr/lib/python3/dist-packages/cloudinit/sources/DataSourceOpenStack.py", line 133, in _get_data
    func=self._crawl_metadata)
  File "/usr/lib/python3/dist-packages/cloudinit/util.py", line 2521, in log_time
    ret = func(*args, **kwargs)
  File "/usr/lib/python3/dist-packages/cloudinit/sources/DataSourceOpenStack.py", line 176, in _crawl_metadata
    'No active metadata service found')
cloudinit.sources.InvalidMetaDataException: No active metadata service found
2019-06-06 07:08:23,970 - __init__.py[DEBUG]: Datasource DataSourceOpenStackLocal [net,ver=None] not updated for events: New instance first boot
2019-06-06 07:08:23,971 - handlers.py[DEBUG]: finish: init-local/search-OpenStackLocal: SUCCESS: no local data found from DataSourceOpenStackLocal
2019-06-06 07:08:23,971 - handlers.py[DEBUG]: start: init-local/search-CloudSigma: searching for local data from DataSourceCloudSigma
2019-06-06 07:08:23,972 - __init__.py[DEBUG]: Seeing if we can get any data from <class 'cloudinit.sources.DataSourceCloudSigma.DataSourceCloudSigma'>
2019-06-06 07:08:23,972 - __init__.py[DEBUG]: Update datasource metadata and network config due to events: New instance first boot
2019-06-06 07:08:23,973 - DataSourceCloudSigma.py[DEBUG]: determining hypervisor product name via dmi data
2019-06-06 07:08:23,973 - util.py[DEBUG]: Running command ['systemd-detect-virt', '--quiet', '--container'] with allowed return codes [0] (shell=False, capture=True)
2019-06-06 07:08:23,982 - util.py[DEBUG]: Running command ['running-in-container'] with allowed return codes [0] (shell=False, capture=True)
2019-06-06 07:08:23,990 - util.py[DEBUG]: Running command ['lxc-is-container'] with allowed return codes [0] (shell=False, capture=True)
2019-06-06 07:08:23,998 - util.py[DEBUG]: Reading from /proc/1/environ (quiet=False)
2019-06-06 07:08:23,998 - util.py[DEBUG]: Read 18 bytes from /proc/1/environ
2019-06-06 07:08:23,999 - util.py[DEBUG]: Reading from /proc/self/status (quiet=False)
2019-06-06 07:08:23,999 - util.py[DEBUG]: Read 912 bytes from /proc/self/status
2019-06-06 07:08:24,000 - util.py[DEBUG]: querying dmi data /sys/class/dmi/id/product_name
2019-06-06 07:08:24,000 - util.py[DEBUG]: did not find /sys/class/dmi/id/product_name
2019-06-06 07:08:24,001 - util.py[DEBUG]: Running command ['/usr/sbin/dmidecode', '--string', 'system-product-name'] with allowed return codes [0] (shell=False, capture=True)
2019-06-06 07:08:24,009 - util.py[DEBUG]: failed dmidecode cmd: ['/usr/sbin/dmidecode', '--string', 'system-product-name']
Unexpected error while running command.
Command: ['/usr/sbin/dmidecode', '--string', 'system-product-name']
Exit code: 1
Reason: -
Stdout: 
Stderr: /dev/mem: Operation not permitted
2019-06-06 07:08:24,009 - DataSourceCloudSigma.py[DEBUG]: system-product-name not available in dmi data
2019-06-06 07:08:24,010 - __init__.py[DEBUG]: Datasource DataSourceCloudSigma not updated for events: New instance first boot
2019-06-06 07:08:24,010 - handlers.py[DEBUG]: finish: init-local/search-CloudSigma: SUCCESS: no local data found from DataSourceCloudSigma
2019-06-06 07:08:24,011 - handlers.py[DEBUG]: start: init-local/search-SmartOS: searching for local data from DataSourceSmartOS
2019-06-06 07:08:24,011 - __init__.py[DEBUG]: Seeing if we can get any data from <class 'cloudinit.sources.DataSourceSmartOS.DataSourceSmartOS'>
2019-06-06 07:08:24,013 - util.py[DEBUG]: Running command ['systemd-detect-virt', '--quiet', '--container'] with allowed return codes [0] (shell=False, capture=True)
2019-06-06 07:08:24,022 - util.py[DEBUG]: Running command ['running-in-container'] with allowed return codes [0] (shell=False, capture=True)
2019-06-06 07:08:24,030 - util.py[DEBUG]: Running command ['lxc-is-container'] with allowed return codes [0] (shell=False, capture=True)
2019-06-06 07:08:24,037 - util.py[DEBUG]: Reading from /proc/1/environ (quiet=False)
2019-06-06 07:08:24,038 - util.py[DEBUG]: Read 18 bytes from /proc/1/environ
2019-06-06 07:08:24,038 - util.py[DEBUG]: Reading from /proc/self/status (quiet=False)
2019-06-06 07:08:24,039 - util.py[DEBUG]: Read 912 bytes from /proc/self/status
2019-06-06 07:08:24,039 - util.py[DEBUG]: querying dmi data /sys/class/dmi/id/product_name
2019-06-06 07:08:24,040 - util.py[DEBUG]: did not find /sys/class/dmi/id/product_name
2019-06-06 07:08:24,041 - util.py[DEBUG]: Running command ['/usr/sbin/dmidecode', '--string', 'system-product-name'] with allowed return codes [0] (shell=False, capture=True)
2019-06-06 07:08:24,049 - util.py[DEBUG]: failed dmidecode cmd: ['/usr/sbin/dmidecode', '--string', 'system-product-name']
Unexpected error while running command.
Command: ['/usr/sbin/dmidecode', '--string', 'system-product-name']
Exit code: 1
Reason: -
Stdout: 
Stderr: /dev/mem: Operation not permitted
2019-06-06 07:08:24,049 - __init__.py[DEBUG]: Update datasource metadata and network config due to events: New instance first boot
2019-06-06 07:08:24,050 - DataSourceSmartOS.py[DEBUG]: Not running on smartos
2019-06-06 07:08:24,050 - __init__.py[DEBUG]: Datasource DataSourceSmartOS [client=None] not updated for events: New instance first boot
2019-06-06 07:08:24,051 - handlers.py[DEBUG]: finish: init-local/search-SmartOS: SUCCESS: no local data found from DataSourceSmartOS
2019-06-06 07:08:24,051 - handlers.py[DEBUG]: start: init-local/search-Scaleway: searching for local data from DataSourceScaleway
2019-06-06 07:08:24,051 - __init__.py[DEBUG]: Seeing if we can get any data from <class 'cloudinit.sources.DataSourceScaleway.DataSourceScaleway'>
2019-06-06 07:08:24,053 - __init__.py[DEBUG]: Update datasource metadata and network config due to events: New instance first boot
2019-06-06 07:08:24,053 - util.py[DEBUG]: Running command ['systemd-detect-virt', '--quiet', '--container'] with allowed return codes [0] (shell=False, capture=True)
2019-06-06 07:08:24,062 - util.py[DEBUG]: Running command ['running-in-container'] with allowed return codes [0] (shell=False, capture=True)
2019-06-06 07:08:24,070 - util.py[DEBUG]: Running command ['lxc-is-container'] with allowed return codes [0] (shell=False, capture=True)
2019-06-06 07:08:24,078 - util.py[DEBUG]: Reading from /proc/1/environ (quiet=False)
2019-06-06 07:08:24,079 - util.py[DEBUG]: Read 18 bytes from /proc/1/environ
2019-06-06 07:08:24,079 - util.py[DEBUG]: Reading from /proc/self/status (quiet=False)
2019-06-06 07:08:24,079 - util.py[DEBUG]: Read 912 bytes from /proc/self/status
2019-06-06 07:08:24,080 - util.py[DEBUG]: querying dmi data /sys/class/dmi/id/sys_vendor
2019-06-06 07:08:24,080 - util.py[DEBUG]: did not find /sys/class/dmi/id/sys_vendor
2019-06-06 07:08:24,081 - util.py[DEBUG]: Running command ['/usr/sbin/dmidecode', '--string', 'system-manufacturer'] with allowed return codes [0] (shell=False, capture=True)
2019-06-06 07:08:24,089 - util.py[DEBUG]: failed dmidecode cmd: ['/usr/sbin/dmidecode', '--string', 'system-manufacturer']
Unexpected error while running command.
Command: ['/usr/sbin/dmidecode', '--string', 'system-manufacturer']
Exit code: 1
Reason: -
Stdout: 
Stderr: /dev/mem: Operation not permitted
2019-06-06 07:08:24,090 - __init__.py[DEBUG]: Datasource DataSourceScaleway not updated for events: New instance first boot
2019-06-06 07:08:24,091 - handlers.py[DEBUG]: finish: init-local/search-Scaleway: SUCCESS: no local data found from DataSourceScaleway
2019-06-06 07:08:24,091 - handlers.py[DEBUG]: start: init-local/search-Ec2Local: searching for local data from DataSourceEc2Local
2019-06-06 07:08:24,091 - __init__.py[DEBUG]: Seeing if we can get any data from <class 'cloudinit.sources.DataSourceEc2.DataSourceEc2Local'>
2019-06-06 07:08:24,092 - __init__.py[DEBUG]: Update datasource metadata and network config due to events: New instance first boot
2019-06-06 07:08:24,092 - util.py[DEBUG]: Reading from /sys/hypervisor/uuid (quiet=False)
2019-06-06 07:08:24,093 - util.py[DEBUG]: Running command ['systemd-detect-virt', '--quiet', '--container'] with allowed return codes [0] (shell=False, capture=True)
2019-06-06 07:08:24,102 - util.py[DEBUG]: Running command ['running-in-container'] with allowed return codes [0] (shell=False, capture=True)
2019-06-06 07:08:24,110 - util.py[DEBUG]: Running command ['lxc-is-container'] with allowed return codes [0] (shell=False, capture=True)
2019-06-06 07:08:24,117 - util.py[DEBUG]: Reading from /proc/1/environ (quiet=False)
2019-06-06 07:08:24,118 - util.py[DEBUG]: Read 18 bytes from /proc/1/environ
2019-06-06 07:08:24,118 - util.py[DEBUG]: Reading from /proc/self/status (quiet=False)
2019-06-06 07:08:24,119 - util.py[DEBUG]: Read 912 bytes from /proc/self/status
2019-06-06 07:08:24,119 - util.py[DEBUG]: querying dmi data /sys/class/dmi/id/product_uuid
2019-06-06 07:08:24,120 - util.py[DEBUG]: did not find /sys/class/dmi/id/product_uuid
2019-06-06 07:08:24,121 - util.py[DEBUG]: Running command ['/usr/sbin/dmidecode', '--string', 'system-uuid'] with allowed return codes [0] (shell=False, capture=True)
2019-06-06 07:08:24,129 - util.py[DEBUG]: failed dmidecode cmd: ['/usr/sbin/dmidecode', '--string', 'system-uuid']
Unexpected error while running command.
Command: ['/usr/sbin/dmidecode', '--string', 'system-uuid']
Exit code: 1
Reason: -
Stdout: 
Stderr: /dev/mem: Operation not permitted
2019-06-06 07:08:24,129 - util.py[DEBUG]: Running command ['systemd-detect-virt', '--quiet', '--container'] with allowed return codes [0] (shell=False, capture=True)
2019-06-06 07:08:24,138 - util.py[DEBUG]: Running command ['running-in-container'] with allowed return codes [0] (shell=False, capture=True)
2019-06-06 07:08:24,146 - util.py[DEBUG]: Running command ['lxc-is-container'] with allowed return codes [0] (shell=False, capture=True)
2019-06-06 07:08:24,154 - util.py[DEBUG]: Reading from /proc/1/environ (quiet=False)
2019-06-06 07:08:24,154 - util.py[DEBUG]: Read 18 bytes from /proc/1/environ
2019-06-06 07:08:24,155 - util.py[DEBUG]: Reading from /proc/self/status (quiet=False)
2019-06-06 07:08:24,155 - util.py[DEBUG]: Read 912 bytes from /proc/self/status
2019-06-06 07:08:24,156 - util.py[DEBUG]: querying dmi data /sys/class/dmi/id/product_serial
2019-06-06 07:08:24,156 - util.py[DEBUG]: did not find /sys/class/dmi/id/product_serial
2019-06-06 07:08:24,157 - util.py[DEBUG]: Running command ['/usr/sbin/dmidecode', '--string', 'system-serial-number'] with allowed return codes [0] (shell=False, capture=True)
2019-06-06 07:08:24,165 - util.py[DEBUG]: failed dmidecode cmd: ['/usr/sbin/dmidecode', '--string', 'system-serial-number']
Unexpected error while running command.
Command: ['/usr/sbin/dmidecode', '--string', 'system-serial-number']
Exit code: 1
Reason: -
Stdout: 
Stderr: /dev/mem: Operation not permitted
2019-06-06 07:08:24,166 - DataSourceEc2.py[DEBUG]: Local Ec2 mode only supported on ('aws',), not unknown
2019-06-06 07:08:24,166 - __init__.py[DEBUG]: Datasource DataSourceEc2Local not updated for events: New instance first boot
2019-06-06 07:08:24,166 - handlers.py[DEBUG]: finish: init-local/search-Ec2Local: SUCCESS: no local data found from DataSourceEc2Local
2019-06-06 07:08:24,167 - main.py[DEBUG]: No local datasource found
2019-06-06 07:08:24,172 - util.py[DEBUG]: Reading from /sys/class/net/can0/name_assign_type (quiet=False)
2019-06-06 07:08:24,172 - util.py[DEBUG]: Reading from /sys/class/net/sit0/name_assign_type (quiet=False)
2019-06-06 07:08:24,173 - util.py[DEBUG]: Reading from /sys/class/net/eth0/name_assign_type (quiet=False)
2019-06-06 07:08:24,173 - __init__.py[DEBUG]: Found unstable nic names: ['can0', 'sit0', 'eth0']; calling udevadm settle
2019-06-06 07:08:24,174 - util.py[DEBUG]: Running command ['udevadm', 'settle'] with allowed return codes [0] (shell=False, capture=True)
2019-06-06 07:08:24,192 - util.py[DEBUG]: Waiting for udev events to settle took 0.019 seconds
2019-06-06 07:08:24,194 - util.py[DEBUG]: Reading from /sys/class/net/eth0/carrier (quiet=False)
2019-06-06 07:08:24,194 - util.py[DEBUG]: Reading from /sys/class/net/eth0/dormant (quiet=False)
2019-06-06 07:08:24,195 - util.py[DEBUG]: Reading from /sys/class/net/eth0/operstate (quiet=False)
2019-06-06 07:08:24,195 - util.py[DEBUG]: Read 5 bytes from /sys/class/net/eth0/operstate
2019-06-06 07:08:24,195 - util.py[DEBUG]: Reading from /sys/class/net/can0/carrier (quiet=False)
2019-06-06 07:08:24,196 - util.py[DEBUG]: Reading from /sys/class/net/can0/dormant (quiet=False)
2019-06-06 07:08:24,196 - util.py[DEBUG]: Reading from /sys/class/net/can0/operstate (quiet=False)
2019-06-06 07:08:24,197 - util.py[DEBUG]: Read 5 bytes from /sys/class/net/can0/operstate
2019-06-06 07:08:24,197 - util.py[DEBUG]: Reading from /sys/class/net/sit0/carrier (quiet=False)
2019-06-06 07:08:24,197 - util.py[DEBUG]: Reading from /sys/class/net/sit0/dormant (quiet=False)
2019-06-06 07:08:24,198 - util.py[DEBUG]: Reading from /sys/class/net/sit0/operstate (quiet=False)
2019-06-06 07:08:24,198 - util.py[DEBUG]: Read 5 bytes from /sys/class/net/sit0/operstate
2019-06-06 07:08:24,199 - util.py[DEBUG]: Reading from /sys/class/net/eth0/address (quiet=False)
2019-06-06 07:08:24,199 - util.py[DEBUG]: Read 18 bytes from /sys/class/net/eth0/address
2019-06-06 07:08:24,199 - util.py[DEBUG]: Reading from /sys/class/net/eth0/address (quiet=False)
2019-06-06 07:08:24,200 - util.py[DEBUG]: Read 18 bytes from /sys/class/net/eth0/address
2019-06-06 07:08:24,200 - stages.py[DEBUG]: applying net config names for {'version': 1, 'config': [{'name': 'eth0', 'subnets': [{'type': 'dhcp'}], 'type': 'physical', 'mac_address': '00:0a:35:00:22:01'}]}
2019-06-06 07:08:24,201 - util.py[DEBUG]: Reading from /sys/class/net/eth0/device/device (quiet=False)
2019-06-06 07:08:24,201 - util.py[DEBUG]: Reading from /sys/class/net/can0/addr_assign_type (quiet=False)
2019-06-06 07:08:24,201 - util.py[DEBUG]: Read 2 bytes from /sys/class/net/can0/addr_assign_type
2019-06-06 07:08:24,202 - util.py[DEBUG]: Reading from /sys/class/net/can0/uevent (quiet=False)
2019-06-06 07:08:24,202 - util.py[DEBUG]: Read 25 bytes from /sys/class/net/can0/uevent
2019-06-06 07:08:24,202 - util.py[DEBUG]: Reading from /sys/class/net/can0/address (quiet=False)
2019-06-06 07:08:24,203 - util.py[DEBUG]: Read 1 bytes from /sys/class/net/can0/address
2019-06-06 07:08:24,203 - util.py[DEBUG]: Reading from /sys/class/net/sit0/addr_assign_type (quiet=False)
2019-06-06 07:08:24,204 - util.py[DEBUG]: Read 2 bytes from /sys/class/net/sit0/addr_assign_type
2019-06-06 07:08:24,204 - util.py[DEBUG]: Reading from /sys/class/net/sit0/uevent (quiet=False)
2019-06-06 07:08:24,204 - util.py[DEBUG]: Read 25 bytes from /sys/class/net/sit0/uevent
2019-06-06 07:08:24,205 - util.py[DEBUG]: Reading from /sys/class/net/sit0/address (quiet=False)
2019-06-06 07:08:24,205 - util.py[DEBUG]: Read 12 bytes from /sys/class/net/sit0/address
2019-06-06 07:08:24,205 - util.py[DEBUG]: Reading from /sys/class/net/lo/addr_assign_type (quiet=False)
2019-06-06 07:08:24,206 - util.py[DEBUG]: Read 2 bytes from /sys/class/net/lo/addr_assign_type
2019-06-06 07:08:24,206 - util.py[DEBUG]: Reading from /sys/class/net/lo/uevent (quiet=False)
2019-06-06 07:08:24,206 - util.py[DEBUG]: Read 23 bytes from /sys/class/net/lo/uevent
2019-06-06 07:08:24,207 - util.py[DEBUG]: Reading from /sys/class/net/lo/address (quiet=False)
2019-06-06 07:08:24,207 - util.py[DEBUG]: Read 18 bytes from /sys/class/net/lo/address
2019-06-06 07:08:24,207 - util.py[DEBUG]: Reading from /sys/class/net/lo/device/device (quiet=False)
2019-06-06 07:08:24,208 - util.py[DEBUG]: Reading from /sys/class/net/eth0/addr_assign_type (quiet=False)
2019-06-06 07:08:24,208 - util.py[DEBUG]: Read 2 bytes from /sys/class/net/eth0/addr_assign_type
2019-06-06 07:08:24,208 - util.py[DEBUG]: Reading from /sys/class/net/eth0/uevent (quiet=False)
2019-06-06 07:08:24,209 - util.py[DEBUG]: Read 25 bytes from /sys/class/net/eth0/uevent
2019-06-06 07:08:24,209 - util.py[DEBUG]: Reading from /sys/class/net/eth0/address (quiet=False)
2019-06-06 07:08:24,210 - util.py[DEBUG]: Read 18 bytes from /sys/class/net/eth0/address
2019-06-06 07:08:24,210 - util.py[DEBUG]: Reading from /sys/class/net/eth0/device/device (quiet=False)
2019-06-06 07:08:24,210 - util.py[DEBUG]: Reading from /sys/class/net/lo/operstate (quiet=False)
2019-06-06 07:08:24,211 - util.py[DEBUG]: Read 8 bytes from /sys/class/net/lo/operstate
2019-06-06 07:08:24,211 - util.py[DEBUG]: Reading from /sys/class/net/eth0/operstate (quiet=False)
2019-06-06 07:08:24,211 - util.py[DEBUG]: Read 5 bytes from /sys/class/net/eth0/operstate
2019-06-06 07:08:24,213 - util.py[DEBUG]: Running command ['ip', '-6', 'addr', 'show', 'permanent', 'scope', 'global'] with allowed return codes [0] (shell=False, capture=True)
2019-06-06 07:08:24,226 - util.py[DEBUG]: Running command ['ip', '-4', 'addr', 'show'] with allowed return codes [0] (shell=False, capture=True)
2019-06-06 07:08:24,237 - __init__.py[DEBUG]: no work necessary for renaming of [['00:0a:35:00:22:01', 'eth0', 'macb', None]]
2019-06-06 07:08:24,238 - stages.py[INFO]: Applying network configuration from fallback bringup=False: {'version': 1, 'config': [{'name': 'eth0', 'subnets': [{'type': 'dhcp'}], 'type': 'physical', 'mac_address': '00:0a:35:00:22:01'}]}
2019-06-06 07:08:24,239 - __init__.py[DEBUG]: Selected renderer 'eni' from priority list: None
2019-06-06 07:08:24,256 - util.py[DEBUG]: Writing to /etc/network/interfaces.d/50-cloud-init.cfg - wb: [644] 367 bytes
2019-06-06 07:08:24,262 - util.py[DEBUG]: Writing to /etc/udev/rules.d/70-persistent-net.rules - wb: [644] 96 bytes
2019-06-06 07:08:24,265 - main.py[DEBUG]: [local] Exiting without datasource
2019-06-06 07:08:24,267 - util.py[DEBUG]: Reading from /proc/uptime (quiet=False)
2019-06-06 07:08:24,267 - util.py[DEBUG]: Read 13 bytes from /proc/uptime
2019-06-06 07:08:24,268 - util.py[DEBUG]: cloud-init mode 'init' took 39.318 seconds (39.32)
2019-06-06 07:08:24,268 - handlers.py[DEBUG]: finish: init-local: SUCCESS: searching for local datasources
2019-06-06 07:08:41,952 - util.py[DEBUG]: Cloud-init v. 19.1-1-gbaa47854-0ubuntu1~16.04.1 running 'init' at Thu, 06 Jun 2019 07:08:41 +0000. Up 72.88 seconds.
2019-06-06 07:08:41,952 - main.py[DEBUG]: No kernel command line url found.
2019-06-06 07:08:41,952 - main.py[DEBUG]: Closing stdin.
2019-06-06 07:08:41,969 - util.py[DEBUG]: Writing to /var/log/cloud-init.log - ab: [644] 0 bytes
2019-06-06 07:08:41,973 - util.py[DEBUG]: Changing the ownership of /var/log/cloud-init.log to 104:4
2019-06-06 07:08:41,974 - util.py[DEBUG]: Running command ['ip', 'addr', 'show'] with allowed return codes [0] (shell=False, capture=True)
2019-06-06 07:08:41,990 - netinfo.py[WARNING]: Could not parse ip addr show: (line:9)     link/can 
2019-06-06 07:08:41,993 - util.py[DEBUG]: Running command ['ip', '-o', 'route', 'list'] with allowed return codes [0] (shell=False, capture=True)
2019-06-06 07:08:42,002 - util.py[DEBUG]: Running command ['ip', '--oneline', '-6', 'route', 'list', 'table', 'all'] with allowed return codes [0, 1] (shell=False, capture=True)
2019-06-06 07:08:42,016 - main.py[DEBUG]: Checking to see if files that we need already exist from a previous run that would allow us to stop early.
2019-06-06 07:08:42,016 - main.py[DEBUG]: Execution continuing, no previous run detected that would allow us to stop early.
2019-06-06 07:08:42,017 - handlers.py[DEBUG]: start: init-network/check-cache: attempting to read from cache [trust]
2019-06-06 07:08:42,017 - util.py[DEBUG]: Reading from /var/lib/cloud/instance/obj.pkl (quiet=False)
2019-06-06 07:08:42,018 - stages.py[DEBUG]: no cache found
2019-06-06 07:08:42,018 - handlers.py[DEBUG]: finish: init-network/check-cache: SUCCESS: no cache found
2019-06-06 07:08:42,019 - util.py[DEBUG]: Attempting to remove /var/lib/cloud/instance
2019-06-06 07:08:42,032 - stages.py[DEBUG]: Using distro class <class 'cloudinit.distros.ubuntu.Distro'>
2019-06-06 07:08:42,034 - __init__.py[DEBUG]: Looking for data source in: ['NoCloud', 'ConfigDrive', 'OpenNebula', 'DigitalOcean', 'Azure', 'AltCloud', 'OVF', 'MAAS', 'GCE', 'OpenStack', 'CloudSigma', 'SmartOS', 'Bigstep', 'Scaleway', 'AliYun', 'Ec2', 'CloudStack', 'None'], via packages ['', 'cloudinit.sources'] that matches dependencies ['FILESYSTEM', 'NETWORK']
2019-06-06 07:08:42,144 - util.py[DEBUG]: Reading from /etc/os-release (quiet=False)
2019-06-06 07:08:42,144 - util.py[DEBUG]: Read 298 bytes from /etc/os-release
2019-06-06 07:08:42,221 - __init__.py[DEBUG]: Searching for network data source in: ['DataSourceNoCloudNet', 'DataSourceAltCloud', 'DataSourceOVFNet', 'DataSourceMAAS', 'DataSourceGCE', 'DataSourceOpenStack', 'DataSourceBigstep', 'DataSourceAliYun', 'DataSourceEc2', 'DataSourceCloudStack', 'DataSourceNone']
2019-06-06 07:08:42,221 - handlers.py[DEBUG]: start: init-network/search-NoCloudNet: searching for network data from DataSourceNoCloudNet
2019-06-06 07:08:42,222 - __init__.py[DEBUG]: Seeing if we can get any data from <class 'cloudinit.sources.DataSourceNoCloud.DataSourceNoCloudNet'>
2019-06-06 07:08:42,222 - __init__.py[DEBUG]: Update datasource metadata and network config due to events: New instance first boot
2019-06-06 07:08:42,223 - util.py[DEBUG]: Running command ['systemd-detect-virt', '--quiet', '--container'] with allowed return codes [0] (shell=False, capture=True)
2019-06-06 07:08:42,232 - util.py[DEBUG]: Running command ['running-in-container'] with allowed return codes [0] (shell=False, capture=True)
2019-06-06 07:08:42,239 - util.py[DEBUG]: Running command ['lxc-is-container'] with allowed return codes [0] (shell=False, capture=True)
2019-06-06 07:08:42,247 - util.py[DEBUG]: Reading from /proc/1/environ (quiet=False)
2019-06-06 07:08:42,248 - util.py[DEBUG]: Read 18 bytes from /proc/1/environ
2019-06-06 07:08:42,248 - util.py[DEBUG]: Reading from /proc/self/status (quiet=False)
2019-06-06 07:08:42,249 - util.py[DEBUG]: Read 910 bytes from /proc/self/status
2019-06-06 07:08:42,249 - util.py[DEBUG]: querying dmi data /sys/class/dmi/id/product_serial
2019-06-06 07:08:42,249 - util.py[DEBUG]: did not find /sys/class/dmi/id/product_serial
2019-06-06 07:08:42,250 - util.py[DEBUG]: Running command ['/usr/sbin/dmidecode', '--string', 'system-serial-number'] with allowed return codes [0] (shell=False, capture=True)
2019-06-06 07:08:42,258 - util.py[DEBUG]: failed dmidecode cmd: ['/usr/sbin/dmidecode', '--string', 'system-serial-number']
Unexpected error while running command.
Command: ['/usr/sbin/dmidecode', '--string', 'system-serial-number']
Exit code: 1
Reason: -
Stdout: 
Stderr: /dev/mem: Operation not permitted
2019-06-06 07:08:42,259 - util.py[DEBUG]: Reading from /var/lib/cloud/seed/nocloud/user-data (quiet=False)
2019-06-06 07:08:42,259 - util.py[DEBUG]: Reading from /var/lib/cloud/seed/nocloud/meta-data (quiet=False)
2019-06-06 07:08:42,260 - util.py[DEBUG]: Reading from /var/lib/cloud/seed/nocloud/vendor-data (quiet=False)
2019-06-06 07:08:42,260 - util.py[DEBUG]: Reading from /var/lib/cloud/seed/nocloud/network-config (quiet=False)
2019-06-06 07:08:42,260 - util.py[DEBUG]: Reading from /var/lib/cloud/seed/nocloud-net/user-data (quiet=False)
2019-06-06 07:08:42,261 - util.py[DEBUG]: Reading from /var/lib/cloud/seed/nocloud-net/meta-data (quiet=False)
2019-06-06 07:08:42,261 - util.py[DEBUG]: Reading from /var/lib/cloud/seed/nocloud-net/vendor-data (quiet=False)
2019-06-06 07:08:42,261 - util.py[DEBUG]: Reading from /var/lib/cloud/seed/nocloud-net/network-config (quiet=False)
2019-06-06 07:08:42,262 - util.py[DEBUG]: Running command ['blkid', '-odevice', '/dev/sr0'] with allowed return codes [0, 2] (shell=False, capture=True)
2019-06-06 07:08:42,270 - util.py[DEBUG]: Running command ['blkid', '-odevice', '/dev/sr1'] with allowed return codes [0, 2] (shell=False, capture=True)
2019-06-06 07:08:42,279 - util.py[DEBUG]: Running command ['blkid', '-tTYPE=vfat', '-odevice'] with allowed return codes [0, 2] (shell=False, capture=True)
2019-06-06 07:08:42,490 - util.py[DEBUG]: Running command ['blkid', '-tTYPE=iso9660', '-odevice'] with allowed return codes [0, 2] (shell=False, capture=True)
2019-06-06 07:08:42,621 - util.py[DEBUG]: Running command ['blkid', '-tLABEL=CIDATA', '-odevice'] with allowed return codes [0, 2] (shell=False, capture=True)
2019-06-06 07:08:42,753 - util.py[DEBUG]: Running command ['blkid', '-tLABEL=cidata', '-odevice'] with allowed return codes [0, 2] (shell=False, capture=True)
2019-06-06 07:08:42,884 - __init__.py[DEBUG]: Datasource DataSourceNoCloudNet [seed=None][dsmode=net] not updated for events: New instance first boot
2019-06-06 07:08:42,885 - handlers.py[DEBUG]: finish: init-network/search-NoCloudNet: SUCCESS: no network data found from DataSourceNoCloudNet
2019-06-06 07:08:42,886 - handlers.py[DEBUG]: start: init-network/search-AltCloud: searching for network data from DataSourceAltCloud
2019-06-06 07:08:42,886 - __init__.py[DEBUG]: Seeing if we can get any data from <class 'cloudinit.sources.DataSourceAltCloud.DataSourceAltCloud'>
2019-06-06 07:08:42,887 - __init__.py[DEBUG]: Update datasource metadata and network config due to events: New instance first boot
2019-06-06 07:08:42,887 - DataSourceAltCloud.py[DEBUG]: Invoked get_data()
2019-06-06 07:08:42,887 - util.py[DEBUG]: Running command ['systemd-detect-virt', '--quiet', '--container'] with allowed return codes [0] (shell=False, capture=True)
2019-06-06 07:08:42,896 - util.py[DEBUG]: Running command ['running-in-container'] with allowed return codes [0] (shell=False, capture=True)
2019-06-06 07:08:42,904 - util.py[DEBUG]: Running command ['lxc-is-container'] with allowed return codes [0] (shell=False, capture=True)
2019-06-06 07:08:42,911 - util.py[DEBUG]: Reading from /proc/1/environ (quiet=False)
2019-06-06 07:08:42,912 - util.py[DEBUG]: Read 18 bytes from /proc/1/environ
2019-06-06 07:08:42,912 - util.py[DEBUG]: Reading from /proc/self/status (quiet=False)
2019-06-06 07:08:42,913 - util.py[DEBUG]: Read 910 bytes from /proc/self/status
2019-06-06 07:08:42,913 - util.py[DEBUG]: querying dmi data /sys/class/dmi/id/product_name
2019-06-06 07:08:42,914 - util.py[DEBUG]: did not find /sys/class/dmi/id/product_name
2019-06-06 07:08:42,915 - util.py[DEBUG]: Running command ['/usr/sbin/dmidecode', '--string', 'system-product-name'] with allowed return codes [0] (shell=False, capture=True)
2019-06-06 07:08:42,922 - util.py[DEBUG]: failed dmidecode cmd: ['/usr/sbin/dmidecode', '--string', 'system-product-name']
Unexpected error while running command.
Command: ['/usr/sbin/dmidecode', '--string', 'system-product-name']
Exit code: 1
Reason: -
Stdout: 
Stderr: /dev/mem: Operation not permitted
2019-06-06 07:08:42,923 - DataSourceAltCloud.py[DEBUG]: cloud_type: UNKNOWN
2019-06-06 07:08:42,924 - __init__.py[DEBUG]: Datasource DataSourceAltCloud [seed=None] not updated for events: New instance first boot
2019-06-06 07:08:42,924 - handlers.py[DEBUG]: finish: init-network/search-AltCloud: SUCCESS: no network data found from DataSourceAltCloud
2019-06-06 07:08:42,925 - handlers.py[DEBUG]: start: init-network/search-OVFNet: searching for network data from DataSourceOVFNet
2019-06-06 07:08:42,925 - __init__.py[DEBUG]: Seeing if we can get any data from <class 'cloudinit.sources.DataSourceOVF.DataSourceOVFNet'>
2019-06-06 07:08:42,926 - __init__.py[DEBUG]: Update datasource metadata and network config due to events: New instance first boot
2019-06-06 07:08:42,926 - util.py[DEBUG]: Running command ['systemd-detect-virt', '--quiet', '--container'] with allowed return codes [0] (shell=False, capture=True)
2019-06-06 07:08:42,935 - util.py[DEBUG]: Running command ['running-in-container'] with allowed return codes [0] (shell=False, capture=True)
2019-06-06 07:08:42,943 - util.py[DEBUG]: Running command ['lxc-is-container'] with allowed return codes [0] (shell=False, capture=True)
2019-06-06 07:08:42,951 - util.py[DEBUG]: Reading from /proc/1/environ (quiet=False)
2019-06-06 07:08:42,951 - util.py[DEBUG]: Read 18 bytes from /proc/1/environ
2019-06-06 07:08:42,952 - util.py[DEBUG]: Reading from /proc/self/status (quiet=False)
2019-06-06 07:08:42,952 - util.py[DEBUG]: Read 910 bytes from /proc/self/status
2019-06-06 07:08:42,953 - util.py[DEBUG]: querying dmi data /sys/class/dmi/id/product_name
2019-06-06 07:08:42,953 - util.py[DEBUG]: did not find /sys/class/dmi/id/product_name
2019-06-06 07:08:42,954 - util.py[DEBUG]: Running command ['/usr/sbin/dmidecode', '--string', 'system-product-name'] with allowed return codes [0] (shell=False, capture=True)
2019-06-06 07:08:42,962 - util.py[DEBUG]: failed dmidecode cmd: ['/usr/sbin/dmidecode', '--string', 'system-product-name']
Unexpected error while running command.
Command: ['/usr/sbin/dmidecode', '--string', 'system-product-name']
Exit code: 1
Reason: -
Stdout: 
Stderr: /dev/mem: Operation not permitted
2019-06-06 07:08:42,963 - DataSourceOVF.py[DEBUG]: No system-product-name found
2019-06-06 07:08:42,964 - util.py[DEBUG]: Reading from /proc/mounts (quiet=False)
2019-06-06 07:08:42,964 - util.py[DEBUG]: Read 942 bytes from /proc/mounts
2019-06-06 07:08:42,965 - util.py[DEBUG]: Fetched {'sysfs': {'fstype': 'sysfs', 'mountpoint': '/sys', 'opts': 'rw,nosuid,nodev,noexec,relatime'}, '/dev/root': {'fstype': 'ext3', 'mountpoint': '/', 'opts': 'rw,relatime,errors=remount-ro'}, 'tmpfs': {'fstype': 'tmpfs', 'mountpoint': '/sys/fs/cgroup', 'opts': 'ro,nosuid,nodev,noexec,mode=755'}, 'devtmpfs': {'fstype': 'devtmpfs', 'mountpoint': '/dev', 'opts': 'rw,relatime,size=1496264k,nr_inodes=374066,mode=755'}, 'tracefs': {'fstype': 'tracefs', 'mountpoint': '/sys/kernel/debug/tracing', 'opts': 'rw,relatime'}, 'configfs': {'fstype': 'configfs', 'mountpoint': '/sys/kernel/config', 'opts': 'rw,relatime'}, 'devpts': {'fstype': 'devpts', 'mountpoint': '/dev/pts', 'opts': 'rw,nosuid,noexec,relatime,gid=5,mode=620,ptmxmode=000'}, 'debugfs': {'fstype': 'debugfs', 'mountpoint': '/sys/kernel/debug', 'opts': 'rw,relatime'}, 'mqueue': {'fstype': 'mqueue', 'mountpoint': '/dev/mqueue', 'opts': 'rw,relatime'}, 'hugetlbfs': {'fstype': 'hugetlbfs', 'mountpoint': '/dev/hugepages', 'opts': 'rw,relatime,pagesize=2M'}, 'cgroup': {'fstype': 'cgroup', 'mountpoint': '/sys/fs/cgroup/systemd', 'opts': 'rw,nosuid,nodev,noexec,relatime,xattr,release_agent=/lib/systemd/systemd-cgroups-agent,name=systemd'}, 'proc': {'fstype': 'proc', 'mountpoint': '/proc', 'opts': 'rw,nosuid,nodev,noexec,relatime'}} mounts from proc
2019-06-06 07:08:42,965 - util.py[DEBUG]: Running command ['blkid', '-tTYPE=iso9660', '-odevice'] with allowed return codes [0, 2] (shell=False, capture=True)
2019-06-06 07:08:43,096 - __init__.py[DEBUG]: Datasource DataSourceOVFNet [seed=None] not updated for events: New instance first boot
2019-06-06 07:08:43,097 - handlers.py[DEBUG]: finish: init-network/search-OVFNet: SUCCESS: no network data found from DataSourceOVFNet
2019-06-06 07:08:43,097 - handlers.py[DEBUG]: start: init-network/search-MAAS: searching for network data from DataSourceMAAS
2019-06-06 07:08:43,098 - __init__.py[DEBUG]: Seeing if we can get any data from <class 'cloudinit.sources.DataSourceMAAS.DataSourceMAAS'>
2019-06-06 07:08:43,098 - __init__.py[DEBUG]: Update datasource metadata and network config due to events: New instance first boot
2019-06-06 07:08:43,099 - __init__.py[DEBUG]: Datasource DataSourceMAAS [None] not updated for events: New instance first boot
2019-06-06 07:08:43,099 - handlers.py[DEBUG]: finish: init-network/search-MAAS: SUCCESS: no network data found from DataSourceMAAS
2019-06-06 07:08:43,100 - handlers.py[DEBUG]: start: init-network/search-GCE: searching for network data from DataSourceGCE
2019-06-06 07:08:43,100 - __init__.py[DEBUG]: Seeing if we can get any data from <class 'cloudinit.sources.DataSourceGCE.DataSourceGCE'>
2019-06-06 07:08:43,103 - __init__.py[DEBUG]: Update datasource metadata and network config due to events: New instance first boot
2019-06-06 07:08:43,104 - util.py[DEBUG]: Running command ['systemd-detect-virt', '--quiet', '--container'] with allowed return codes [0] (shell=False, capture=True)
2019-06-06 07:08:43,112 - util.py[DEBUG]: Running command ['running-in-container'] with allowed return codes [0] (shell=False, capture=True)
2019-06-06 07:08:43,120 - util.py[DEBUG]: Running command ['lxc-is-container'] with allowed return codes [0] (shell=False, capture=True)
2019-06-06 07:08:43,128 - util.py[DEBUG]: Reading from /proc/1/environ (quiet=False)
2019-06-06 07:08:43,129 - util.py[DEBUG]: Read 18 bytes from /proc/1/environ
2019-06-06 07:08:43,129 - util.py[DEBUG]: Reading from /proc/self/status (quiet=False)
2019-06-06 07:08:43,129 - util.py[DEBUG]: Read 910 bytes from /proc/self/status
2019-06-06 07:08:43,130 - util.py[DEBUG]: querying dmi data /sys/class/dmi/id/product_name
2019-06-06 07:08:43,130 - util.py[DEBUG]: did not find /sys/class/dmi/id/product_name
2019-06-06 07:08:43,131 - util.py[DEBUG]: Running command ['/usr/sbin/dmidecode', '--string', 'system-product-name'] with allowed return codes [0] (shell=False, capture=True)
2019-06-06 07:08:43,139 - util.py[DEBUG]: failed dmidecode cmd: ['/usr/sbin/dmidecode', '--string', 'system-product-name']
Unexpected error while running command.
Command: ['/usr/sbin/dmidecode', '--string', 'system-product-name']
Exit code: 1
Reason: -
Stdout: 
Stderr: /dev/mem: Operation not permitted
2019-06-06 07:08:43,140 - util.py[DEBUG]: Running command ['systemd-detect-virt', '--quiet', '--container'] with allowed return codes [0] (shell=False, capture=True)
2019-06-06 07:08:43,149 - util.py[DEBUG]: Running command ['running-in-container'] with allowed return codes [0] (shell=False, capture=True)
2019-06-06 07:08:43,156 - util.py[DEBUG]: Running command ['lxc-is-container'] with allowed return codes [0] (shell=False, capture=True)
2019-06-06 07:08:43,164 - util.py[DEBUG]: Reading from /proc/1/environ (quiet=False)
2019-06-06 07:08:43,165 - util.py[DEBUG]: Read 18 bytes from /proc/1/environ
2019-06-06 07:08:43,165 - util.py[DEBUG]: Reading from /proc/self/status (quiet=False)
2019-06-06 07:08:43,166 - util.py[DEBUG]: Read 910 bytes from /proc/self/status
2019-06-06 07:08:43,166 - util.py[DEBUG]: querying dmi data /sys/class/dmi/id/product_serial
2019-06-06 07:08:43,166 - util.py[DEBUG]: did not find /sys/class/dmi/id/product_serial
2019-06-06 07:08:43,167 - util.py[DEBUG]: Running command ['/usr/sbin/dmidecode', '--string', 'system-serial-number'] with allowed return codes [0] (shell=False, capture=True)
2019-06-06 07:08:43,175 - util.py[DEBUG]: failed dmidecode cmd: ['/usr/sbin/dmidecode', '--string', 'system-serial-number']
Unexpected error while running command.
Command: ['/usr/sbin/dmidecode', '--string', 'system-serial-number']
Exit code: 1
Reason: -
Stdout: 
Stderr: /dev/mem: Operation not permitted
2019-06-06 07:08:43,176 - DataSourceGCE.py[DEBUG]: Not running on google cloud. product-name=N/A serial=N/A
2019-06-06 07:08:43,176 - util.py[DEBUG]: Crawl of GCE metadata service took 0.073 seconds
2019-06-06 07:08:43,176 - DataSourceGCE.py[DEBUG]: Not running on GCE.
2019-06-06 07:08:43,177 - __init__.py[DEBUG]: Datasource DataSourceGCE not updated for events: New instance first boot
2019-06-06 07:08:43,177 - handlers.py[DEBUG]: finish: init-network/search-GCE: SUCCESS: no network data found from DataSourceGCE
2019-06-06 07:08:43,178 - handlers.py[DEBUG]: start: init-network/search-OpenStack: searching for network data from DataSourceOpenStack
2019-06-06 07:08:43,178 - __init__.py[DEBUG]: Seeing if we can get any data from <class 'cloudinit.sources.DataSourceOpenStack.DataSourceOpenStack'>
2019-06-06 07:08:43,179 - __init__.py[DEBUG]: Update datasource metadata and network config due to events: New instance first boot
2019-06-06 07:08:43,196 - util.py[DEBUG]: Resolving URL: http://169.254.169.254 took 0.016 seconds
2019-06-06 07:08:43,197 - url_helper.py[DEBUG]: [0/1] open 'http://169.254.169.254/openstack' with {'headers': {'User-Agent': 'Cloud-Init/19.1-1-gbaa47854-0ubuntu1~16.04.1'}, 'url': 'http://169.254.169.254/openstack', 'allow_redirects': True, 'method': 'GET', 'timeout': 10.0} configuration
2019-06-06 07:08:53,213 - url_helper.py[DEBUG]: Calling 'http://169.254.169.254/openstack' failed [10/-1s]: request error [HTTPConnectionPool(host='169.254.169.254', port=80): Max retries exceeded with url: /openstack (Caused by ConnectTimeoutError(<requests.packages.urllib3.connection.HTTPConnection object at 0x7f8744ae80>, 'Connection to 169.254.169.254 timed out. (connect timeout=10.0)'))]
2019-06-06 07:08:53,214 - DataSourceOpenStack.py[DEBUG]: Giving up on OpenStack md from ['http://169.254.169.254/openstack'] after 10 seconds
2019-06-06 07:08:53,214 - util.py[WARNING]: No active metadata service found
2019-06-06 07:08:53,215 - util.py[DEBUG]: No active metadata service found
Traceback (most recent call last):
  File "/usr/lib/python3/dist-packages/cloudinit/sources/DataSourceOpenStack.py", line 139, in _get_data
    results = self._crawl_metadata()
  File "/usr/lib/python3/dist-packages/cloudinit/sources/DataSourceOpenStack.py", line 176, in _crawl_metadata
    'No active metadata service found')
cloudinit.sources.InvalidMetaDataException: No active metadata service found
2019-06-06 07:08:53,216 - __init__.py[DEBUG]: Datasource DataSourceOpenStack [net,ver=None] not updated for events: New instance first boot
2019-06-06 07:08:53,217 - handlers.py[DEBUG]: finish: init-network/search-OpenStack: SUCCESS: no network data found from DataSourceOpenStack
2019-06-06 07:08:53,217 - handlers.py[DEBUG]: start: init-network/search-Bigstep: searching for network data from DataSourceBigstep
2019-06-06 07:08:53,217 - __init__.py[DEBUG]: Seeing if we can get any data from <class 'cloudinit.sources.DataSourceBigstep.DataSourceBigstep'>
2019-06-06 07:08:53,218 - __init__.py[DEBUG]: Update datasource metadata and network config due to events: New instance first boot
2019-06-06 07:08:53,218 - util.py[DEBUG]: Reading from /var/lib/cloud/data/seed/bigstep/url (quiet=False)
2019-06-06 07:08:53,219 - __init__.py[DEBUG]: Datasource DataSourceBigstep not updated for events: New instance first boot
2019-06-06 07:08:53,219 - handlers.py[DEBUG]: finish: init-network/search-Bigstep: SUCCESS: no network data found from DataSourceBigstep
2019-06-06 07:08:53,220 - handlers.py[DEBUG]: start: init-network/search-AliYun: searching for network data from DataSourceAliYun
2019-06-06 07:08:53,220 - __init__.py[DEBUG]: Seeing if we can get any data from <class 'cloudinit.sources.DataSourceAliYun.DataSourceAliYun'>
2019-06-06 07:08:53,220 - __init__.py[DEBUG]: Update datasource metadata and network config due to events: New instance first boot
2019-06-06 07:08:53,221 - util.py[DEBUG]: Running command ['systemd-detect-virt', '--quiet', '--container'] with allowed return codes [0] (shell=False, capture=True)
2019-06-06 07:08:53,230 - util.py[DEBUG]: Running command ['running-in-container'] with allowed return codes [0] (shell=False, capture=True)
2019-06-06 07:08:53,237 - util.py[DEBUG]: Running command ['lxc-is-container'] with allowed return codes [0] (shell=False, capture=True)
2019-06-06 07:08:53,245 - util.py[DEBUG]: Reading from /proc/1/environ (quiet=False)
2019-06-06 07:08:53,246 - util.py[DEBUG]: Read 18 bytes from /proc/1/environ
2019-06-06 07:08:53,246 - util.py[DEBUG]: Reading from /proc/self/status (quiet=False)
2019-06-06 07:08:53,247 - util.py[DEBUG]: Read 911 bytes from /proc/self/status
2019-06-06 07:08:53,247 - util.py[DEBUG]: querying dmi data /sys/class/dmi/id/product_name
2019-06-06 07:08:53,248 - util.py[DEBUG]: did not find /sys/class/dmi/id/product_name
2019-06-06 07:08:53,249 - util.py[DEBUG]: Running command ['/usr/sbin/dmidecode', '--string', 'system-product-name'] with allowed return codes [0] (shell=False, capture=True)
2019-06-06 07:08:53,256 - util.py[DEBUG]: failed dmidecode cmd: ['/usr/sbin/dmidecode', '--string', 'system-product-name']
Unexpected error while running command.
Command: ['/usr/sbin/dmidecode', '--string', 'system-product-name']
Exit code: 1
Reason: -
Stdout: 
Stderr: /dev/mem: Operation not permitted
2019-06-06 07:08:53,257 - DataSourceEc2.py[DEBUG]: strict_mode: warn, cloud_name=no-ec2-metadata cloud_platform=ec2
2019-06-06 07:08:53,257 - __init__.py[DEBUG]: Datasource DataSourceAliYun not updated for events: New instance first boot
2019-06-06 07:08:53,258 - handlers.py[DEBUG]: finish: init-network/search-AliYun: SUCCESS: no network data found from DataSourceAliYun
2019-06-06 07:08:53,259 - handlers.py[DEBUG]: start: init-network/search-Ec2: searching for network data from DataSourceEc2
2019-06-06 07:08:53,259 - __init__.py[DEBUG]: Seeing if we can get any data from <class 'cloudinit.sources.DataSourceEc2.DataSourceEc2'>
2019-06-06 07:08:53,260 - __init__.py[DEBUG]: Update datasource metadata and network config due to events: New instance first boot
2019-06-06 07:08:53,260 - util.py[DEBUG]: Reading from /sys/hypervisor/uuid (quiet=False)
2019-06-06 07:08:53,260 - util.py[DEBUG]: Running command ['systemd-detect-virt', '--quiet', '--container'] with allowed return codes [0] (shell=False, capture=True)
2019-06-06 07:08:53,269 - util.py[DEBUG]: Running command ['running-in-container'] with allowed return codes [0] (shell=False, capture=True)
2019-06-06 07:08:53,277 - util.py[DEBUG]: Running command ['lxc-is-container'] with allowed return codes [0] (shell=False, capture=True)
2019-06-06 07:08:53,285 - util.py[DEBUG]: Reading from /proc/1/environ (quiet=False)
2019-06-06 07:08:53,285 - util.py[DEBUG]: Read 18 bytes from /proc/1/environ
2019-06-06 07:08:53,286 - util.py[DEBUG]: Reading from /proc/self/status (quiet=False)
2019-06-06 07:08:53,286 - util.py[DEBUG]: Read 911 bytes from /proc/self/status
2019-06-06 07:08:53,287 - util.py[DEBUG]: querying dmi data /sys/class/dmi/id/product_uuid
2019-06-06 07:08:53,287 - util.py[DEBUG]: did not find /sys/class/dmi/id/product_uuid
2019-06-06 07:08:53,288 - util.py[DEBUG]: Running command ['/usr/sbin/dmidecode', '--string', 'system-uuid'] with allowed return codes [0] (shell=False, capture=True)
2019-06-06 07:08:53,296 - util.py[DEBUG]: failed dmidecode cmd: ['/usr/sbin/dmidecode', '--string', 'system-uuid']
Unexpected error while running command.
Command: ['/usr/sbin/dmidecode', '--string', 'system-uuid']
Exit code: 1
Reason: -
Stdout: 
Stderr: /dev/mem: Operation not permitted
2019-06-06 07:08:53,297 - util.py[DEBUG]: Running command ['systemd-detect-virt', '--quiet', '--container'] with allowed return codes [0] (shell=False, capture=True)
2019-06-06 07:08:53,306 - util.py[DEBUG]: Running command ['running-in-container'] with allowed return codes [0] (shell=False, capture=True)
2019-06-06 07:08:53,313 - util.py[DEBUG]: Running command ['lxc-is-container'] with allowed return codes [0] (shell=False, capture=True)
2019-06-06 07:08:53,321 - util.py[DEBUG]: Reading from /proc/1/environ (quiet=False)
2019-06-06 07:08:53,322 - util.py[DEBUG]: Read 18 bytes from /proc/1/environ
2019-06-06 07:08:53,322 - util.py[DEBUG]: Reading from /proc/self/status (quiet=False)
2019-06-06 07:08:53,323 - util.py[DEBUG]: Read 911 bytes from /proc/self/status
2019-06-06 07:08:53,323 - util.py[DEBUG]: querying dmi data /sys/class/dmi/id/product_serial
2019-06-06 07:08:53,323 - util.py[DEBUG]: did not find /sys/class/dmi/id/product_serial
2019-06-06 07:08:53,324 - util.py[DEBUG]: Running command ['/usr/sbin/dmidecode', '--string', 'system-serial-number'] with allowed return codes [0] (shell=False, capture=True)
2019-06-06 07:08:53,332 - util.py[DEBUG]: failed dmidecode cmd: ['/usr/sbin/dmidecode', '--string', 'system-serial-number']
Unexpected error while running command.
Command: ['/usr/sbin/dmidecode', '--string', 'system-serial-number']
Exit code: 1
Reason: -
Stdout: 
Stderr: /dev/mem: Operation not permitted
2019-06-06 07:08:53,333 - DataSourceEc2.py[DEBUG]: strict_mode: warn, cloud_name=unknown cloud_platform=ec2
2019-06-06 07:08:53,334 - util.py[DEBUG]: Resolving URL: http://169.254.169.254 took 0.000 seconds
2019-06-06 07:08:53,371 - util.py[DEBUG]: Resolving URL: http://instance-data.:8773 took 0.037 seconds
2019-06-06 07:08:53,372 - DataSourceEc2.py[DEBUG]: Removed the following from metadata urls: ['http://instance-data.:8773']
2019-06-06 07:08:53,372 - url_helper.py[DEBUG]: [0/1] open 'http://169.254.169.254/2009-04-04/meta-data/instance-id' with {'headers': {'User-Agent': 'Cloud-Init/19.1-1-gbaa47854-0ubuntu1~16.04.1'}, 'url': 'http://169.254.169.254/2009-04-04/meta-data/instance-id', 'allow_redirects': True, 'method': 'GET', 'timeout': 50.0} configuration
2019-06-06 07:09:43,430 - url_helper.py[WARNING]: Calling 'http://169.254.169.254/2009-04-04/meta-data/instance-id' failed [50/120s]: request error [HTTPConnectionPool(host='169.254.169.254', port=80): Max retries exceeded with url: /2009-04-04/meta-data/instance-id (Caused by ConnectTimeoutError(<requests.packages.urllib3.connection.HTTPConnection object at 0x7f873ee898>, 'Connection to 169.254.169.254 timed out. (connect timeout=50.0)'))]
2019-06-06 07:09:43,430 - url_helper.py[DEBUG]: Please wait 1 seconds while we wait to try again
2019-06-06 07:09:44,434 - url_helper.py[DEBUG]: [0/1] open 'http://169.254.169.254/2009-04-04/meta-data/instance-id' with {'headers': {'User-Agent': 'Cloud-Init/19.1-1-gbaa47854-0ubuntu1~16.04.1'}, 'url': 'http://169.254.169.254/2009-04-04/meta-data/instance-id', 'allow_redirects': True, 'method': 'GET', 'timeout': 50.0} configuration
2019-06-06 07:10:34,491 - url_helper.py[WARNING]: Calling 'http://169.254.169.254/2009-04-04/meta-data/instance-id' failed [101/120s]: request error [HTTPConnectionPool(host='169.254.169.254', port=80): Max retries exceeded with url: /2009-04-04/meta-data/instance-id (Caused by ConnectTimeoutError(<requests.packages.urllib3.connection.HTTPConnection object at 0x7f873f8198>, 'Connection to 169.254.169.254 timed out. (connect timeout=50.0)'))]
2019-06-06 07:10:34,491 - url_helper.py[DEBUG]: Please wait 1 seconds while we wait to try again
2019-06-06 07:10:35,493 - url_helper.py[DEBUG]: [0/1] open 'http://169.254.169.254/2009-04-04/meta-data/instance-id' with {'headers': {'User-Agent': 'Cloud-Init/19.1-1-gbaa47854-0ubuntu1~16.04.1'}, 'url': 'http://169.254.169.254/2009-04-04/meta-data/instance-id', 'allow_redirects': True, 'method': 'GET', 'timeout': 17.0} configuration
2019-06-06 07:10:52,501 - url_helper.py[WARNING]: Calling 'http://169.254.169.254/2009-04-04/meta-data/instance-id' failed [119/120s]: request error [HTTPConnectionPool(host='169.254.169.254', port=80): Max retries exceeded with url: /2009-04-04/meta-data/instance-id (Caused by ConnectTimeoutError(<requests.packages.urllib3.connection.HTTPConnection object at 0x7f873f8940>, 'Connection to 169.254.169.254 timed out. (connect timeout=17.0)'))]
2019-06-06 07:10:52,786 - url_helper.py[DEBUG]: Please wait 1 seconds while we wait to try again
2019-06-06 07:10:53,787 - DataSourceEc2.py[CRITICAL]: Giving up on md from ['http://169.254.169.254/2009-04-04/meta-data/instance-id'] after 120 seconds
2019-06-06 07:10:53,788 - util.py[DEBUG]: Crawl of metadata service took 120.454 seconds
2019-06-06 07:10:53,788 - __init__.py[DEBUG]: Datasource DataSourceEc2 not updated for events: New instance first boot
2019-06-06 07:10:53,789 - handlers.py[DEBUG]: finish: init-network/search-Ec2: SUCCESS: no network data found from DataSourceEc2
2019-06-06 07:10:53,789 - handlers.py[DEBUG]: start: init-network/search-CloudStack: searching for network data from DataSourceCloudStack
2019-06-06 07:10:53,789 - __init__.py[DEBUG]: Seeing if we can get any data from <class 'cloudinit.sources.DataSourceCloudStack.DataSourceCloudStack'>
2019-06-06 07:10:53,790 - DataSourceCloudStack.py[DEBUG]: Using /var/lib/dhcp lease directory
2019-06-06 07:10:53,791 - DataSourceCloudStack.py[DEBUG]: Found DHCP identifier 172.23.84.250
2019-06-06 07:10:53,791 - DataSourceCloudStack.py[DEBUG]: Found DHCP identifier 172.23.84.251
2019-06-06 07:10:53,792 - __init__.py[DEBUG]: Update datasource metadata and network config due to events: New instance first boot
2019-06-06 07:10:53,793 - url_helper.py[DEBUG]: [0/1] open 'http://172.23.84.251/latest/meta-data/instance-id' with {'headers': {'User-Agent': 'Cloud-Init/19.1-1-gbaa47854-0ubuntu1~16.04.1'}, 'url': 'http://172.23.84.251/latest/meta-data/instance-id', 'allow_redirects': True, 'method': 'GET', 'timeout': 50.0} configuration
2019-06-06 07:10:53,799 - url_helper.py[WARNING]: Calling 'http://172.23.84.251/latest/meta-data/instance-id' failed [0/120s]: request error [HTTPConnectionPool(host='172.23.84.251', port=80): Max retries exceeded with url: /latest/meta-data/instance-id (Caused by NewConnectionError('<requests.packages.urllib3.connection.HTTPConnection object at 0x7f873ee550>: Failed to establish a new connection: [Errno 111] Connection refused',))]
2019-06-06 07:10:53,800 - url_helper.py[DEBUG]: Please wait 1 seconds while we wait to try again
2019-06-06 07:10:54,801 - url_helper.py[DEBUG]: [0/1] open 'http://172.23.84.251/latest/meta-data/instance-id' with {'headers': {'User-Agent': 'Cloud-Init/19.1-1-gbaa47854-0ubuntu1~16.04.1'}, 'url': 'http://172.23.84.251/latest/meta-data/instance-id', 'allow_redirects': True, 'method': 'GET', 'timeout': 50.0} configuration
2019-06-06 07:10:54,808 - url_helper.py[WARNING]: Calling 'http://172.23.84.251/latest/meta-data/instance-id' failed [1/120s]: request error [HTTPConnectionPool(host='172.23.84.251', port=80): Max retries exceeded with url: /latest/meta-data/instance-id (Caused by NewConnectionError('<requests.packages.urllib3.connection.HTTPConnection object at 0x7f873f8b00>: Failed to establish a new connection: [Errno 111] Connection refused',))]
2019-06-06 07:10:54,808 - url_helper.py[DEBUG]: Please wait 1 seconds while we wait to try again
2019-06-06 07:10:55,810 - url_helper.py[DEBUG]: [0/1] open 'http://172.23.84.251/latest/meta-data/instance-id' with {'headers': {'User-Agent': 'Cloud-Init/19.1-1-gbaa47854-0ubuntu1~16.04.1'}, 'url': 'http://172.23.84.251/latest/meta-data/instance-id', 'allow_redirects': True, 'method': 'GET', 'timeout': 50.0} configuration
2019-06-06 07:10:55,816 - url_helper.py[WARNING]: Calling 'http://172.23.84.251/latest/meta-data/instance-id' failed [2/120s]: request error [HTTPConnectionPool(host='172.23.84.251', port=80): Max retries exceeded with url: /latest/meta-data/instance-id (Caused by NewConnectionError('<requests.packages.urllib3.connection.HTTPConnection object at 0x7f87401358>: Failed to establish a new connection: [Errno 111] Connection refused',))]
2019-06-06 07:10:55,817 - url_helper.py[DEBUG]: Please wait 1 seconds while we wait to try again
2019-06-06 07:10:56,819 - url_helper.py[DEBUG]: [0/1] open 'http://172.23.84.251/latest/meta-data/instance-id' with {'headers': {'User-Agent': 'Cloud-Init/19.1-1-gbaa47854-0ubuntu1~16.04.1'}, 'url': 'http://172.23.84.251/latest/meta-data/instance-id', 'allow_redirects': True, 'method': 'GET', 'timeout': 50.0} configuration
2019-06-06 07:10:56,825 - url_helper.py[WARNING]: Calling 'http://172.23.84.251/latest/meta-data/instance-id' failed [3/120s]: request error [HTTPConnectionPool(host='172.23.84.251', port=80): Max retries exceeded with url: /latest/meta-data/instance-id (Caused by NewConnectionError('<requests.packages.urllib3.connection.HTTPConnection object at 0x7f87401b70>: Failed to establish a new connection: [Errno 111] Connection refused',))]
2019-06-06 07:10:56,826 - url_helper.py[DEBUG]: Please wait 1 seconds while we wait to try again
2019-06-06 07:10:57,827 - url_helper.py[DEBUG]: [0/1] open 'http://172.23.84.251/latest/meta-data/instance-id' with {'headers': {'User-Agent': 'Cloud-Init/19.1-1-gbaa47854-0ubuntu1~16.04.1'}, 'url': 'http://172.23.84.251/latest/meta-data/instance-id', 'allow_redirects': True, 'method': 'GET', 'timeout': 50.0} configuration
2019-06-06 07:10:59,160 - url_helper.py[WARNING]: Calling 'http://172.23.84.251/latest/meta-data/instance-id' failed [5/120s]: request error [HTTPConnectionPool(host='172.23.84.251', port=80): Max retries exceeded with url: /latest/meta-data/instance-id (Caused by NewConnectionError('<requests.packages.urllib3.connection.HTTPConnection object at 0x7f874019e8>: Failed to establish a new connection: [Errno 111] Connection refused',))]
2019-06-06 07:10:59,161 - url_helper.py[DEBUG]: Please wait 1 seconds while we wait to try again
2019-06-06 07:11:00,163 - url_helper.py[DEBUG]: [0/1] open 'http://172.23.84.251/latest/meta-data/instance-id' with {'headers': {'User-Agent': 'Cloud-Init/19.1-1-gbaa47854-0ubuntu1~16.04.1'}, 'url': 'http://172.23.84.251/latest/meta-data/instance-id', 'allow_redirects': True, 'method': 'GET', 'timeout': 50.0} configuration
2019-06-06 07:11:00,169 - url_helper.py[WARNING]: Calling 'http://172.23.84.251/latest/meta-data/instance-id' failed [6/120s]: request error [HTTPConnectionPool(host='172.23.84.251', port=80): Max retries exceeded with url: /latest/meta-data/instance-id (Caused by NewConnectionError('<requests.packages.urllib3.connection.HTTPConnection object at 0x7f873f8160>: Failed to establish a new connection: [Errno 111] Connection refused',))]
2019-06-06 07:11:00,170 - url_helper.py[DEBUG]: Please wait 2 seconds while we wait to try again
2019-06-06 07:11:02,172 - url_helper.py[DEBUG]: [0/1] open 'http://172.23.84.251/latest/meta-data/instance-id' with {'headers': {'User-Agent': 'Cloud-Init/19.1-1-gbaa47854-0ubuntu1~16.04.1'}, 'url': 'http://172.23.84.251/latest/meta-data/instance-id', 'allow_redirects': True, 'method': 'GET', 'timeout': 50.0} configuration
2019-06-06 07:11:02,178 - url_helper.py[WARNING]: Calling 'http://172.23.84.251/latest/meta-data/instance-id' failed [8/120s]: request error [HTTPConnectionPool(host='172.23.84.251', port=80): Max retries exceeded with url: /latest/meta-data/instance-id (Caused by NewConnectionError('<requests.packages.urllib3.connection.HTTPConnection object at 0x7f873eee48>: Failed to establish a new connection: [Errno 111] Connection refused',))]
2019-06-06 07:11:02,179 - url_helper.py[DEBUG]: Please wait 2 seconds while we wait to try again
2019-06-06 07:11:04,181 - url_helper.py[DEBUG]: [0/1] open 'http://172.23.84.251/latest/meta-data/instance-id' with {'headers': {'User-Agent': 'Cloud-Init/19.1-1-gbaa47854-0ubuntu1~16.04.1'}, 'url': 'http://172.23.84.251/latest/meta-data/instance-id', 'allow_redirects': True, 'method': 'GET', 'timeout': 50.0} configuration
2019-06-06 07:11:04,577 - url_helper.py[WARNING]: Calling 'http://172.23.84.251/latest/meta-data/instance-id' failed [10/120s]: request error [HTTPConnectionPool(host='172.23.84.251', port=80): Max retries exceeded with url: /latest/meta-data/instance-id (Caused by NewConnectionError('<requests.packages.urllib3.connection.HTTPConnection object at 0x7f873ee390>: Failed to establish a new connection: [Errno 111] Connection refused',))]
2019-06-06 07:11:04,578 - url_helper.py[DEBUG]: Please wait 2 seconds while we wait to try again
2019-06-06 07:11:06,581 - url_helper.py[DEBUG]: [0/1] open 'http://172.23.84.251/latest/meta-data/instance-id' with {'headers': {'User-Agent': 'Cloud-Init/19.1-1-gbaa47854-0ubuntu1~16.04.1'}, 'url': 'http://172.23.84.251/latest/meta-data/instance-id', 'allow_redirects': True, 'method': 'GET', 'timeout': 50.0} configuration
2019-06-06 07:11:06,587 - url_helper.py[WARNING]: Calling 'http://172.23.84.251/latest/meta-data/instance-id' failed [12/120s]: request error [HTTPConnectionPool(host='172.23.84.251', port=80): Max retries exceeded with url: /latest/meta-data/instance-id (Caused by NewConnectionError('<requests.packages.urllib3.connection.HTTPConnection object at 0x7f874093c8>: Failed to establish a new connection: [Errno 111] Connection refused',))]
2019-06-06 07:11:06,588 - url_helper.py[DEBUG]: Please wait 2 seconds while we wait to try again
2019-06-06 07:11:08,590 - url_helper.py[DEBUG]: [0/1] open 'http://172.23.84.251/latest/meta-data/instance-id' with {'headers': {'User-Agent': 'Cloud-Init/19.1-1-gbaa47854-0ubuntu1~16.04.1'}, 'url': 'http://172.23.84.251/latest/meta-data/instance-id', 'allow_redirects': True, 'method': 'GET', 'timeout': 50.0} configuration
2019-06-06 07:11:08,598 - url_helper.py[WARNING]: Calling 'http://172.23.84.251/latest/meta-data/instance-id' failed [14/120s]: request error [HTTPConnectionPool(host='172.23.84.251', port=80): Max retries exceeded with url: /latest/meta-data/instance-id (Caused by NewConnectionError('<requests.packages.urllib3.connection.HTTPConnection object at 0x7f873eea90>: Failed to establish a new connection: [Errno 111] Connection refused',))]
2019-06-06 07:11:08,599 - url_helper.py[DEBUG]: Please wait 2 seconds while we wait to try again
2019-06-06 07:11:10,600 - url_helper.py[DEBUG]: [0/1] open 'http://172.23.84.251/latest/meta-data/instance-id' with {'headers': {'User-Agent': 'Cloud-Init/19.1-1-gbaa47854-0ubuntu1~16.04.1'}, 'url': 'http://172.23.84.251/latest/meta-data/instance-id', 'allow_redirects': True, 'method': 'GET', 'timeout': 50.0} configuration
2019-06-06 07:11:10,606 - url_helper.py[WARNING]: Calling 'http://172.23.84.251/latest/meta-data/instance-id' failed [16/120s]: request error [HTTPConnectionPool(host='172.23.84.251', port=80): Max retries exceeded with url: /latest/meta-data/instance-id (Caused by NewConnectionError('<requests.packages.urllib3.connection.HTTPConnection object at 0x7f87401358>: Failed to establish a new connection: [Errno 111] Connection refused',))]
2019-06-06 07:11:10,607 - url_helper.py[DEBUG]: Please wait 3 seconds while we wait to try again
2019-06-06 07:11:13,610 - url_helper.py[DEBUG]: [0/1] open 'http://172.23.84.251/latest/meta-data/instance-id' with {'headers': {'User-Agent': 'Cloud-Init/19.1-1-gbaa47854-0ubuntu1~16.04.1'}, 'url': 'http://172.23.84.251/latest/meta-data/instance-id', 'allow_redirects': True, 'method': 'GET', 'timeout': 50.0} configuration
2019-06-06 07:11:13,617 - url_helper.py[WARNING]: Calling 'http://172.23.84.251/latest/meta-data/instance-id' failed [19/120s]: request error [HTTPConnectionPool(host='172.23.84.251', port=80): Max retries exceeded with url: /latest/meta-data/instance-id (Caused by NewConnectionError('<requests.packages.urllib3.connection.HTTPConnection object at 0x7f873f80b8>: Failed to establish a new connection: [Errno 111] Connection refused',))]
2019-06-06 07:11:13,617 - url_helper.py[DEBUG]: Please wait 3 seconds while we wait to try again
