Cloud-init v. 19.1-1-gbaa47854-0ubuntu1~16.04.1 running 'init-local' at Thu, 06 Jun 2019 07:07:44 +0000. Up 16.11 seconds.
2019-06-06 07:08:23,294 - util.py[WARNING]: No active metadata service found
Cloud-init v. 19.1-1-gbaa47854-0ubuntu1~16.04.1 running 'init' at Thu, 06 Jun 2019 07:08:41 +0000. Up 72.88 seconds.
2019-06-06 07:08:41,990 - netinfo.py[WARNING]: Could not parse ip addr show: (line:9)     link/can 
ci-info: +++++++++++++++++++++++++++++++++++++++Net device info+++++++++++++++++++++++++++++++++++++++
ci-info: +--------+-------+-----------------------------+---------------+--------+-------------------+
ci-info: | Device |   Up  |           Address           |      Mask     | Scope  |     Hw-Address    |
ci-info: +--------+-------+-----------------------------+---------------+--------+-------------------+
ci-info: |  can0  | False |              .              |       .       |   .    |         .         |
ci-info: |  eth0  |  True |        172.23.19.138        | 255.255.252.0 | global | 00:0a:35:00:22:01 |
ci-info: |  eth0  |  True | fe80::20a:35ff:fe00:2201/64 |       .       |  link  | 00:0a:35:00:22:01 |
ci-info: |   lo   |  True |          127.0.0.1          |   255.0.0.0   |  host  |         .         |
ci-info: |   lo   |  True |           ::1/128           |       .       |  host  |         .         |
ci-info: |  sit0  | False |              .              |       .       |   .    |         .         |
ci-info: +--------+-------+-----------------------------+---------------+--------+-------------------+
ci-info: ++++++++++++++++++++++++++++++Route IPv4 info++++++++++++++++++++++++++++++
ci-info: +-------+-------------+---------------+---------------+-----------+-------+
ci-info: | Route | Destination |    Gateway    |    Genmask    | Interface | Flags |
ci-info: +-------+-------------+---------------+---------------+-----------+-------+
ci-info: |   0   |   0.0.0.0   | 172.23.19.254 |    0.0.0.0    |    eth0   |   UG  |
ci-info: |   1   | 172.23.16.0 |    0.0.0.0    | 255.255.252.0 |    eth0   |   U   |
ci-info: +-------+-------------+---------------+---------------+-----------+-------+
ci-info: +++++++++++++++++++Route IPv6 info+++++++++++++++++++
ci-info: +-------+-------------+---------+-----------+-------+
ci-info: | Route | Destination | Gateway | Interface | Flags |
ci-info: +-------+-------------+---------+-----------+-------+
ci-info: |   1   |    local    |    ::   |    eth0   |   U   |
ci-info: |   2   |  fe80::/64  |    ::   |    eth0   |   U   |
ci-info: |   3   |   ff00::/8  |    ::   |    eth0   |   U   |
ci-info: +-------+-------------+---------+-----------+-------+
2019-06-06 07:08:53,214 - util.py[WARNING]: No active metadata service found
2019-06-06 07:09:43,430 - url_helper.py[WARNING]: Calling 'http://169.254.169.254/2009-04-04/meta-data/instance-id' failed [50/120s]: request error [HTTPConnectionPool(host='169.254.169.254', port=80): Max retries exceeded with url: /2009-04-04/meta-data/instance-id (Caused by ConnectTimeoutError(<requests.packages.urllib3.connection.HTTPConnection object at 0x7f873ee898>, 'Connection to 169.254.169.254 timed out. (connect timeout=50.0)'))]
2019-06-06 07:10:34,491 - url_helper.py[WARNING]: Calling 'http://169.254.169.254/2009-04-04/meta-data/instance-id' failed [101/120s]: request error [HTTPConnectionPool(host='169.254.169.254', port=80): Max retries exceeded with url: /2009-04-04/meta-data/instance-id (Caused by ConnectTimeoutError(<requests.packages.urllib3.connection.HTTPConnection object at 0x7f873f8198>, 'Connection to 169.254.169.254 timed out. (connect timeout=50.0)'))]
2019-06-06 07:10:52,501 - url_helper.py[WARNING]: Calling 'http://169.254.169.254/2009-04-04/meta-data/instance-id' failed [119/120s]: request error [HTTPConnectionPool(host='169.254.169.254', port=80): Max retries exceeded with url: /2009-04-04/meta-data/instance-id (Caused by ConnectTimeoutError(<requests.packages.urllib3.connection.HTTPConnection object at 0x7f873f8940>, 'Connection to 169.254.169.254 timed out. (connect timeout=17.0)'))]
2019-06-06 07:10:53,787 - DataSourceEc2.py[CRITICAL]: Giving up on md from ['http://169.254.169.254/2009-04-04/meta-data/instance-id'] after 120 seconds
2019-06-06 07:10:53,799 - url_helper.py[WARNING]: Calling 'http://172.23.84.251/latest/meta-data/instance-id' failed [0/120s]: request error [HTTPConnectionPool(host='172.23.84.251', port=80): Max retries exceeded with url: /latest/meta-data/instance-id (Caused by NewConnectionError('<requests.packages.urllib3.connection.HTTPConnection object at 0x7f873ee550>: Failed to establish a new connection: [Errno 111] Connection refused',))]
2019-06-06 07:10:54,808 - url_helper.py[WARNING]: Calling 'http://172.23.84.251/latest/meta-data/instance-id' failed [1/120s]: request error [HTTPConnectionPool(host='172.23.84.251', port=80): Max retries exceeded with url: /latest/meta-data/instance-id (Caused by NewConnectionError('<requests.packages.urllib3.connection.HTTPConnection object at 0x7f873f8b00>: Failed to establish a new connection: [Errno 111] Connection refused',))]
2019-06-06 07:10:55,816 - url_helper.py[WARNING]: Calling 'http://172.23.84.251/latest/meta-data/instance-id' failed [2/120s]: request error [HTTPConnectionPool(host='172.23.84.251', port=80): Max retries exceeded with url: /latest/meta-data/instance-id (Caused by NewConnectionError('<requests.packages.urllib3.connection.HTTPConnection object at 0x7f87401358>: Failed to establish a new connection: [Errno 111] Connection refused',))]
2019-06-06 07:10:56,825 - url_helper.py[WARNING]: Calling 'http://172.23.84.251/latest/meta-data/instance-id' failed [3/120s]: request error [HTTPConnectionPool(host='172.23.84.251', port=80): Max retries exceeded with url: /latest/meta-data/instance-id (Caused by NewConnectionError('<requests.packages.urllib3.connection.HTTPConnection object at 0x7f87401b70>: Failed to establish a new connection: [Errno 111] Connection refused',))]
2019-06-06 07:10:59,160 - url_helper.py[WARNING]: Calling 'http://172.23.84.251/latest/meta-data/instance-id' failed [5/120s]: request error [HTTPConnectionPool(host='172.23.84.251', port=80): Max retries exceeded with url: /latest/meta-data/instance-id (Caused by NewConnectionError('<requests.packages.urllib3.connection.HTTPConnection object at 0x7f874019e8>: Failed to establish a new connection: [Errno 111] Connection refused',))]
2019-06-06 07:11:00,169 - url_helper.py[WARNING]: Calling 'http://172.23.84.251/latest/meta-data/instance-id' failed [6/120s]: request error [HTTPConnectionPool(host='172.23.84.251', port=80): Max retries exceeded with url: /latest/meta-data/instance-id (Caused by NewConnectionError('<requests.packages.urllib3.connection.HTTPConnection object at 0x7f873f8160>: Failed to establish a new connection: [Errno 111] Connection refused',))]
2019-06-06 07:11:02,178 - url_helper.py[WARNING]: Calling 'http://172.23.84.251/latest/meta-data/instance-id' failed [8/120s]: request error [HTTPConnectionPool(host='172.23.84.251', port=80): Max retries exceeded with url: /latest/meta-data/instance-id (Caused by NewConnectionError('<requests.packages.urllib3.connection.HTTPConnection object at 0x7f873eee48>: Failed to establish a new connection: [Errno 111] Connection refused',))]
2019-06-06 07:11:04,577 - url_helper.py[WARNING]: Calling 'http://172.23.84.251/latest/meta-data/instance-id' failed [10/120s]: request error [HTTPConnectionPool(host='172.23.84.251', port=80): Max retries exceeded with url: /latest/meta-data/instance-id (Caused by NewConnectionError('<requests.packages.urllib3.connection.HTTPConnection object at 0x7f873ee390>: Failed to establish a new connection: [Errno 111] Connection refused',))]
2019-06-06 07:11:06,587 - url_helper.py[WARNING]: Calling 'http://172.23.84.251/latest/meta-data/instance-id' failed [12/120s]: request error [HTTPConnectionPool(host='172.23.84.251', port=80): Max retries exceeded with url: /latest/meta-data/instance-id (Caused by NewConnectionError('<requests.packages.urllib3.connection.HTTPConnection object at 0x7f874093c8>: Failed to establish a new connection: [Errno 111] Connection refused',))]
2019-06-06 07:11:08,598 - url_helper.py[WARNING]: Calling 'http://172.23.84.251/latest/meta-data/instance-id' failed [14/120s]: request error [HTTPConnectionPool(host='172.23.84.251', port=80): Max retries exceeded with url: /latest/meta-data/instance-id (Caused by NewConnectionError('<requests.packages.urllib3.connection.HTTPConnection object at 0x7f873eea90>: Failed to establish a new connection: [Errno 111] Connection refused',))]
                                                                                                                                                                                                                                                                                                                                                                                                                                                                                                                                                                                                                                                                                                                                                                                                                                                                                                            